File: rawhc/NBMPO_s2_HIIc.raw
[Header]
TITLE,
BYAPP,HeatCapacity,3.8.2,4.0
INFO,PPMS Heat Capacity Option 3.8.2 Build 2,APPNAME
DATATYPE,TIME,1
DATATYPE,COMMENT,2
STARTUPAXIS, X, 1, LINEAR, AUTO
STARTUPAXIS, Y1, 4, LINEAR, AUTO
[Data]
Time Stamp (Seconds),Comment (),Therm Res (Ohms),Platform Temp (Kelvin),Heater Power (Watts),Platform Temp Fit (Kelvin),Sample Temp Fit (Kelvin)
7999318.72,Error: Warning: Current field is 3999.853 Oe;
7999318.88,Error: but addenda was obtained at -0.046 Oe.
8000847.14,CALFILE: He3Puck843_possibly_fixed.cal - Addenda #0 measured on 12/23/2013 from 0.41394759 to 98.318705 K
8000847.41,BEGIN:PULSE:PARAMS
8000847.41,ThResSigmaPerCycle=2315.17697579208
8000847.41,TempSigmaPerCycle=0.086413569383704
8000847.41,NBinsOn=128
8000847.41,NBinsOff=128
8000847.41,Period=300
8000847.41,Iterations=1
8000847.41,HtrOverLoad=0
8000847.41,NCycRec=285
8000847.41,ThFreqHz=244.140625
8000847.41,NSampPerBin=285
8000847.41,PPMSTemp=0.4397774
8000847.41,EstTau=300
8000847.41,ThermOverload=0
8000847.41,ThResCorrFact=1
8000847.41,AvgHtrOnResistance=1137.27505447154
8000847.41,IsAddenda=0
8000847.41,AddendafromTbl=2.0766940831451E-8
8000847.41,AddendafromTblMinMidMax=6.75106618149726E-9|1.91772769336358E-8|4.45275540105452E-8
8000847.41,AddendaOffsetMinMidMax=0|0|0
8000847.41,AddendaErrfromTbl=4.0101856482827E-10
8000847.41,CondfromTbl=8.52414333916167E-8
8000847.41,TempMinMidMax=0.492854084592174|1.05967668892599|1.6264992932598
8000847.41,CondfromTblMinMidMax=9.69419827162165E-8|2.03318957012814E-7|3.18093769618763E-7
8000847.41,DisableTau2Fitting=1
8000847.41,HtrCurrOn=1.37940775544088E-5
8000847.41,StableStartTemperature=0.419907175103416
8000847.41,TimeStamp=8000847.41
8000847.41,PPMSStatus=5905
8000847.41,PuckTemp=0.439777
8000847.41,SystemTemp=0.4398
8000847.41,Field=3999.853
8000847.41,Pressure=9.19E-5
8000847.41,SampleTemp=1.0995936
8000847.41,TempRise=0.9731194
8000847.41,SampHC=9350.214
8000847.41,SampHCErr=338.2
8000847.41,AddendaHC=0.020766941
8000847.41,AddendaHCErr=0.000401
8000847.41,TotalHC=13.122727
8000847.41,TotalHCErr=0.4739
8000847.41,FitDeviation=47.239593
8000847.41,TimeConsttau1=66.758204
8000847.41,TimeConsttau2=0
8000847.41,SampleCoupling=100
8000847.41,DebyeTemp=15.692211
8000847.41,DebyeTempErr=0.1857
8000847.41,CalCorrection=1
8000847.41,ThermCondWire=1.9657E-7
8000847.41,AddendaOffset=0
8000847.41,END:PULSE:PARAMS
8000848.581456,,5185.67759413375,0.492854084592174,2.32654399243914E-7,0.622664135558473,0.622664135558473
8000849.752912,,4245.84150416987,0.552178803656415,2.31495743974611E-7,0.641633964559294,0.641633964559294
8000850.924368,,3698.8266846182,0.60009903050687,2.30419609992164E-7,0.660273819441173,0.660273819441173
8000852.095824,,3331.17545379039,0.641088934283529,2.29444865060287E-7,0.678589439998555,0.678589439998555
8000853.26728,,3063.99414015216,0.677119672037164,2.2857211348458E-7,0.696586466183998,0.696586466183998
8000854.438736,,2857.08726915936,0.709947223902202,2.27758651002684E-7,0.714270439844883,0.714270439844883
8000855.610192,,2694.81192656935,0.739629640305067,2.27036640101501E-7,0.731646806429926,0.731646806429926
8000856.781648,,2560.30263780051,0.767243954032303,2.26351424696817E-7,0.748720916666001,0.748720916666001
8000857.953104,,2449.21703623533,0.792351292999719,2.2574235179766E-7,0.765498028205796,0.765498028205796
8000859.12456,,2354.60939196397,0.81568990628559,2.25165038515007E-7,0.78198330724681,0.78198330724681
8000860.296016,,2273.58682062606,0.837349953391819,2.24629019448315E-7,0.798181830122186,0.798181830122186
8000861.467472,,2202.93461267114,0.857687536096324,2.24150610848768E-7,0.814098584863872,0.814098584863872
8000862.638928,,2140.56500185858,0.876995704630499,2.23695635877465E-7,0.829738472738592,0.829738472738592
8000863.810384,,2085.95181695594,0.895090259518169,2.23279336464526E-7,0.845106309757103,0.845106309757103
8000864.98184,,2036.59177929134,0.91237815398492,2.22902048335284E-7,0.860206828157189,0.860206828157189
8000866.153296,,1992.79587551966,0.928432977202876,2.22540136426293E-7,0.875044677860871,0.875044677860871
8000867.324752,,1952.9572795747,0.943592402184997,2.22198703762616E-7,0.88962442790626,0.88962442790626
8000868.496208,,1917.46869009281,0.957513488650573,2.21860158336804E-7,0.903950567854508,0.903950567854508
8000869.667664,,1884.87094944149,0.97060114984575,2.21579290523203E-7,0.918027509172285,0.918027509172285
8000870.83912,,1855.11504629313,0.982801513248026,2.21309635935725E-7,0.931859586590206,0.931859586590206
8000872.010576,,1828.1135850441,0.994141989751606,2.21048643061839E-7,0.94545105943763,0.94545105943763
8000873.182032,,1803.23972826155,1.00486860799083,2.20811218106331E-7,0.958806112954244,0.958806112954244
8000874.353488,,1780.47579062823,1.01496593912044,2.20588027904942E-7,0.971928859578824,0.971928859578824
8000875.524944,,1759.29041956313,1.02464398834637,2.2035819034196E-7,0.984823340215588,0.984823340215588
8000876.6964,,1739.85726954908,1.03379411844493,2.2016407395441E-7,0.997493525478517,0.997493525478517
8000877.867856,,1722.22630358996,1.04234990831277,2.1998519949698E-7,1.00994331691403,1.00994331691403
8000879.039312,,1705.92408917965,1.05050017003104,2.19790075933431E-7,1.02217654820238,1.02217654820238
8000880.210768,,1691.22568719403,1.05806518357002,2.1963315791278E-7,1.03419698633819,1.03419698633819
8000881.382224,,1678.40745384613,1.06483863944717,2.19486983102785E-7,1.04600833279042,1.04600833279042
8000882.55368,,1666.74704041575,1.07112676381211,2.19357124543974E-7,1.05761422464213,1.05761422464213
8000883.725136,,1655.9475767793,1.07705917751205,2.19240694998485E-7,1.06901823571052,1.06901823571052
8000884.896592,,1643.47958673217,1.08404251790869,2.19109359248209E-7,1.08022387764734,1.08022387764734
8000886.068048,,1629.41550341227,1.09209913676215,2.18934983510241E-7,1.09123460102032,1.09123460102032
8000887.239504,,1615.09100445678,1.10050842837261,2.18768598035199E-7,1.10205379637563,1.10205379637563
8000888.41096,,1601.10881816653,1.1089234056503,2.18605234088153E-7,1.112684795282,1.112684795282
8000889.582416,,1587.43854377195,1.11735657978673,2.18462483676555E-7,1.12313087135657,1.12313087135657
8000890.753872,,1573.93584370628,1.12589481296119,2.18283206348725E-7,1.13339524127296,1.13339524127296
8000891.925328,,1560.84873537821,1.13437630367001,2.18123065364877E-7,1.14348106575177,1.14348106575177
8000893.096784,,1548.27896884169,1.14272140640533,2.17967355955424E-7,1.15339145053389,1.15339145053389
8000894.26824,,1536.20735195871,1.15092663499718,2.17826149880358E-7,1.16312944733683,1.16312944733683
8000895.439696,,1524.52306731537,1.15905365000083,2.17659495825049E-7,1.17269805479444,1.17269805479444
8000896.611152,,1513.06247946508,1.16720869084259,2.17513119579854E-7,1.18210021938032,1.18210021938032
8000897.782608,,1502.15486839535,1.17514544321424,2.17375069322918E-7,1.19133883631506,1.19133883631506
8000898.954064,,1491.65996759897,1.18294903286044,2.17240107739046E-7,1.20041675045785,1.20041675045785
8000900.12552,,1481.55303349308,1.1906245144069,2.17104474704508E-7,1.20933675718245,1.20933675718245
8000901.296976,,1471.85920619232,1.19813912091216,2.16975019016097E-7,1.21810160323798,1.21810160323798
8000902.468432,,1462.40382666672,1.20561782667769,2.16839520271692E-7,1.22671398759474,1.22671398759474
8000903.639888,,1453.37828758723,1.21289815291908,2.16718860587007E-7,1.2351765622753,1.2351765622753
8000904.811344,,1444.75956367535,1.21998342519091,2.16599745238853E-7,1.24349193317115,1.24349193317115
8000905.9828,,1436.42829886624,1.2269596742829,2.16472572482706E-7,1.25166266084513,1.25166266084513
8000907.154256,,1428.53758086122,1.23368572880771,2.16374607830533E-7,1.25969126131991,1.25969126131991
8000908.325712,,1420.75614701391,1.24043488136157,2.16257305399177E-7,1.26758020685272,1.26758020685272
8000909.497168,,1413.36844278557,1.24695225070083,2.16153834851542E-7,1.27533192669671,1.27533192669671
8000910.668624,,1406.41687064087,1.25318500174659,2.16055198748702E-7,1.28294880784892,1.28294880784892
8000911.84008,,1399.6119623827,1.2593826479156,2.15949982429335E-7,1.29043319578533,1.29043319578533
8000913.011536,,1393.18597989051,1.26532483596831,2.15859470879554E-7,1.29778739518315,1.29778739518315
8000914.182992,,1386.98588833386,1.27114260722047,2.15775069530834E-7,1.30501367063042,1.30501367063042
8000915.354448,,1381.33647367347,1.27651747755631,2.15693286839711E-7,1.31211424732344,1.31211424732344
8000916.525904,,1375.66461531451,1.28198600889269,2.1560613254326E-7,1.31909131175189,1.31909131175189
8000917.69736,,1369.40908861546,1.2881030979647,2.15520186858009E-7,1.32594701237218,1.32594701237218
8000918.868816,,1362.60729974061,1.29485884508464,2.1541953640317E-7,1.33268346026902,1.33268346026902
8000920.040272,,1355.41701546624,1.30212176699654,2.15304986919546E-7,1.33930272980545,1.33930272980545
8000921.211728,,1348.17087308224,1.30957056352267,2.15195070445516E-7,1.34580685926163,1.34580685926163
8000922.383184,,1340.97894980986,1.31709558750379,2.15079849511226E-7,1.35219785146251,1.35219785146251
8000923.55464,,1333.70216873723,1.32484684883752,2.14974163176392E-7,1.35847767439451,1.35847767439451
8000924.726096,,1326.46763151656,1.33269392269793,2.14852160590375E-7,1.36464826181158,1.36464826181158
8000925.897552,,1319.00950324465,1.34093460215294,2.14738819717949E-7,1.37071151383063,1.37071151383063
8000927.069008,,1311.98745418548,1.34883753504585,2.1462789606792E-7,1.37666929751662,1.37666929751662
8000928.240464,,1305.1512992233,1.35666918888052,2.1452274689362E-7,1.38252344745755,1.38252344745755
8000929.41192,,1298.58809030086,1.36431958014433,2.1441323328999E-7,1.38827576632932,1.38827576632932
8000930.583376,,1292.02739274634,1.37209907172864,2.14305868328492E-7,1.39392802545087,1.39392802545087
8000931.754832,,1285.62615383702,1.37981996851073,2.14203472101922E-7,1.3994819653296,1.3994819653296
8000932.926288,,1279.04671354718,1.38789358131966,2.14099665828954E-7,1.40493929619736,1.40493929619736
8000934.097744,,1273.03788248424,1.39539210119062,2.13999821114915E-7,1.41030169853704,1.41030169853704
8000935.2692,,1267.26734058374,1.40270842945078,2.13901587882475E-7,1.41557082360009,1.41557082360009
8000936.440656,,1261.53610820006,1.41008923564518,2.13811143477761E-7,1.42074829391495,1.42074829391495
8000937.612112,,1256.00139696499,1.41732757696262,2.137340609413E-7,1.42583570378669,1.42583570378669
8000938.783568,,1250.40937367044,1.42475377956477,2.13620652923808E-7,1.43083461978799,1.43083461978799
8000939.955024,,1245.00842582143,1.43203640172001,2.13535580124422E-7,1.43574658124145,1.43574658124145
8000941.12648,,1239.99978007699,1.43888891018564,2.13453058837566E-7,1.44057310069368,1.44057310069368
8000942.297936,,1235.16571405618,1.44559468664475,2.13366844572048E-7,1.44531566438101,1.44531566438101
8000943.469392,,1230.48143130522,1.45218074069642,2.13284860445726E-7,1.44997573268716,1.44997573268716
8000944.640848,,1225.98811825799,1.45858132102932,2.13213149514594E-7,1.45455474059296,1.45455474059296
8000945.812304,,1221.43027627295,1.46515847332945,2.13124853752011E-7,1.45905409811818,1.45905409811818
8000946.98376,,1216.87457555949,1.47181935774078,2.13057238669941E-7,1.46347519075576,1.46347519075576
8000948.155216,,1212.75548276782,1.4779179929155,2.12976328864685E-7,1.46781937989844,1.46781937989844
8000949.326672,,1208.78382049078,1.48386801929461,2.12902200711155E-7,1.47208800325797,1.47208800325797
8000950.498128,,1205.01986155846,1.48957107509433,2.12835525660018E-7,1.476282375277,1.476282375277
8000951.669584,,1201.32796566772,1.49522661877063,2.12767709142749E-7,1.48040378753391,1.48040378753391
8000952.84104,,1197.76642298976,1.50074127204464,2.12707345727873E-7,1.48445350914045,1.48445350914045
8000954.012496,,1194.08996540287,1.50649537179902,2.1263939492047E-7,1.48843278713261,1.48843278713261
8000955.183952,,1190.77287134762,1.51174146612584,2.12581381582925E-7,1.49234284685457,1.49234284685457
8000956.355408,,1187.60402730601,1.51680204047317,2.12525718322711E-7,1.49618489233604,1.49618489233604
8000957.526864,,1184.45900160647,1.52187252377518,2.12471263673696E-7,1.49996010666301,1.49996010666301
8000958.69832,,1181.5447309656,1.52661418793071,2.12418084780947E-7,1.50366965234208,1.50366965234208
8000959.869776,,1178.65187304069,1.53136265654184,2.12364771598064E-7,1.50731467165841,1.50731467165841
8000961.041232,,1175.8316597373,1.53603232803089,2.12317904341575E-7,1.51089628702749,1.51089628702749
8000962.212688,,1173.15319332641,1.5405047230908,2.12267881266956E-7,1.51441560134073,1.51441560134073
8000963.384144,,1170.54620837717,1.54489319386138,2.12219402528868E-7,1.51787369830511,1.51787369830511
8000964.5556,,1168.07145355778,1.54909178430248,2.12169916614782E-7,1.52127164277687,1.52127164277687
8000965.727056,,1165.68491384101,1.55317122034709,2.12128689543887E-7,1.52461048108941,1.52461048108941
8000966.898512,,1163.40644225117,1.55709417695145,2.12085850991395E-7,1.52789124137549,1.52789124137549
8000968.069968,,1161.16328842492,1.56098355651397,2.12042676713569E-7,1.53111493388386,1.53111493388386
8000969.241424,,1158.82311649059,1.56507024600651,2.12005344056538E-7,1.53428255129027,1.53428255129027
8000970.41288,,1156.38661376995,1.56935705772693,2.11948136459792E-7,1.53739506900323,1.53739506900323
8000971.584336,,1154.404034192,1.57286948701033,2.11919532661419E-7,1.54045344546431,1.54045344546431
8000972.755792,,1152.6296337969,1.57603172389951,2.11883610050786E-7,1.5434586224433,1.5434586224433
8000973.927248,,1150.77323063035,1.57935909430699,2.11850574678017E-7,1.54641152532821,1.54641152532821
8000975.098704,,1149.00641720991,1.58254407143235,2.11816599274316E-7,1.54931306341021,1.54931306341021
8000976.27016,,1147.36808008518,1.58551342226074,2.11785511108479E-7,1.55216413016366,1.55216413016366
8000977.441616,,1145.70706134281,1.58853969360597,2.11754825813041E-7,1.5549656035212,1.5549656035212
8000978.613072,,1143.83064653926,1.59197770455255,2.1172420766267E-7,1.55771834614411,1.55771834614411
8000979.784528,,1142.16180290316,1.59505273915581,2.11688016471771E-7,1.56042320568797,1.56042320568797
8000980.955984,,1140.74478338082,1.59767667170304,2.11653571052604E-7,1.56308101506364,1.56308101506364
8000982.12744,,1139.28126389878,1.6003992446701,2.11632487501691E-7,1.56569259269379,1.56569259269379
8000983.298896,,1137.96065446912,1.6028669659258,2.1160858385798E-7,1.56825874276487,1.56825874276487
8000984.470352,,1136.77621405164,1.60508917142842,2.11584814504402E-7,1.57078025547476,1.57078025547476
8000985.641808,,1135.50117934087,1.60749084245232,2.11557016446829E-7,1.5732579072761,1.5732579072761
8000986.813264,,1134.43939941969,1.60949837778086,2.11537611522581E-7,1.57569246111541,1.57569246111541
8000987.98472,,1133.23444509162,1.6117849770278,2.11518273743399E-7,1.57808466666796,1.57808466666796
8000989.156176,,1131.89882032535,1.61432998886515,2.11490072815426E-7,1.5804352605687,1.5804352605687
8000990.327632,,1130.90886552669,1.6162234563832,2.11469996440511E-7,1.582744966639,1.582744966639
8000991.499088,,1129.96459118872,1.61803523222417,2.11448845744531E-7,1.58501449610964,1.58501449610964
8000992.670544,,1128.9448965068,1.61999797364655,2.11435282441077E-7,1.58724454783973,1.58724454783973
8000993.842,,1128.12645491936,1.62157805693726,2.1141863046456E-7,1.58943580853197,1.58943580853197
8000995.013456,,1127.26880955691,1.62323835619125,2.11400165571244E-7,1.59158895294407,1.59158895294407
8000996.184912,,1126.30732573983,1.62510520763814,2.1137948489073E-7,1.59370464409656,1.59370464409656
8000997.356368,,1125.59129509263,1.6264992932598,2.11362698624079E-7,1.59578353347694,1.59578353347694
8000998.527824,,1135.16912363093,1.60811792945784,0,1.58819605084082,1.58819605084082
8000999.69928,,1153.23267932315,1.57495502685638,0,1.57123341700607,1.57123341700607
8001000.870736,,1171.02706924524,1.54408108866533,0,1.5545658427712,1.5545658427712
8001002.042192,,1188.4453619947,1.51545374641775,0,1.53818819566865,1.53818819566865
8001003.213648,,1205.53730909181,1.488783310025,0,1.52209543250854,1.52209543250854
8001004.385104,,1222.23283015386,1.46399409986423,0,1.50628259782564,1.50628259782564
8001005.55656,,1238.5650223665,1.44086966857301,0,1.49074482235346,1.49074482235346
8001006.728016,,1254.63553004187,1.41913087507595,0,1.47547732152485,1.47547732152485
8001007.899472,,1270.04692259773,1.39917001089024,0,1.46047539399868,1.46047539399868
8001009.070928,,1285.27871269413,1.3802427887362,0,1.44573442021213,1.44573442021213
8001010.242384,,1300.22470912122,1.36239962567333,0,1.43124986095823,1.43124986095823
8001011.41384,,1314.70660475667,1.34576045113696,0,1.41701725598805,1.41701725598805
8001012.585296,,1328.72196753892,1.33023342501199,0,1.40303222263725,1.40303222263725
8001013.756752,,1342.19886660365,1.3158097583826,0,1.38929045447657,1.38929045447657
8001014.928208,,1354.89359352079,1.30265543184861,0,1.37578771998569,1.37578771998569
8001016.099664,,1366.59625080312,1.29088354985567,0,1.36251986125024,1.36251986125024
8001017.27112,,1376.87231892957,1.28081545445594,0,1.34948279268144,1.34948279268144
8001018.442576,,1385.31416323352,1.27272568990906,0,1.33667249975803,1.33667249975803
8001019.614032,,1393.88963874627,1.2646698445434,0,1.32408503779007,1.32408503779007
8001020.785488,,1403.05517997845,1.25623463520032,0,1.31171653070422,1.31171653070422
8001021.956944,,1412.45898393761,1.24776209421457,0,1.29956316985021,1.29956316985021
8001023.1284,,1422.11268222255,1.23924985713449,0,1.28762121282804,1.28762121282804
8001024.299856,,1431.89038921184,1.23081347412287,0,1.27588698233554,1.27588698233554
8001025.471312,,1441.92047545938,1.22234651853109,0,1.26435686503605,1.26435686503605
8001026.642768,,1452.02693372714,1.2140003761294,0,1.25302731044575,1.25302731044575
8001027.814224,,1462.31981480093,1.20568494914704,0,1.24189482984035,1.24189482984035
8001028.98568,,1472.45662096734,1.19767158771888,0,1.23095599518079,1.23095599518079
8001030.157136,,1482.78656454454,1.18967912628898,0,1.22020743805768,1.22020743805768
8001031.328592,,1493.26906711402,1.18174169986108,0,1.20964584865401,1.20964584865401
8001032.500048,,1503.94502431971,1.17383088142336,0,1.19926797472601,1.19926797472601
8001033.671504,,1514.79164880216,1.16596634294499,0,1.18907062060162,1.18907062060162
8001034.84296,,1525.56102889448,1.15832414764905,0,1.17905064619651,1.17905064619651
8001036.014416,,1536.49750747756,1.15072716251574,0,1.16920496604708,1.16920496604708
8001037.185872,,1547.43525496234,1.1432887254272,0,1.1595305483604,1.1595305483604
8001038.357328,,1558.33683874906,1.13602812356842,0,1.15002441408061,1.15002441408061
8001039.528784,,1569.36763902413,1.12883189821931,0,1.14068363597159,1.14068363597159
8001040.70024,,1580.21669556815,1.12189688538795,0,1.13150533771553,1.13150533771553
8001041.871696,,1590.74247297221,1.11529926764281,0,1.12248669302726,1.12248669302726
8001043.043152,,1601.67797344358,1.10857676934448,0,1.11362492478395,1.11362492478395
8001044.214608,,1612.61944832706,1.1019807938384,0,1.10491730416992,1.10491730416992
8001045.386064,,1623.51183257655,1.09553955054336,0,1.09636114983638,1.09636114983638
8001046.55752,,1634.27632211029,1.08929265380877,0,1.08795382707573,1.08795382707573
8001047.728976,,1644.89533735282,1.08324214986238,0,1.07969274701028,1.07969274701028
8001048.900432,,1655.15208116401,1.07750038625364,0,1.07157536579505,1.07157536579505
8001050.071888,,1664.88860171941,1.07214011437086,0,1.06359918383441,1.06359918383441
8001051.243344,,1673.66498666577,1.06738168086938,0,1.0557617450124,1.0557617450124
8001052.4148,,1681.48602081987,1.06319827004203,0,1.04806063593643,1.04806063593643
8001053.586256,,1688.7761782311,1.05934717543743,0,1.0404934851941,1.0404934851941
8001054.757712,,1696.54262317725,1.05530375851073,0,1.03305796262295,1.03305796262295
8001055.929168,,1704.66935689586,1.05113767091167,0,1.02575177859297,1.02575177859297
8001057.100624,,1713.39995563972,1.0467325864643,0,1.01857268330154,1.01857268330154
8001058.27208,,1722.50971806861,1.04221031819776,0,1.01151846608063,1.01151846608063
8001059.443536,,1732.11699570021,1.03751881614717,0,1.00458695471606,1.00458695471606
8001060.614992,,1742.05698992804,1.03274421765682,0,0.997776014778642,0.997776014778642
8001061.786448,,1752.34778260114,1.02788122725095,0,0.991083548966898,0.991083548966898
8001062.957904,,1763.08684123025,1.02288798746661,0,0.984507496461236,0.984507496461236
8001064.12936,,1774.02630701939,1.01788172580466,0,0.978045832289364,0.978045832289364
8001065.300816,,1784.43854415801,1.0131869394142,0,0.971696566702736,0.971696566702736
8001066.472272,,1795.61513594971,1.00821850845791,0,0.965457744563847,0.965457744563847
8001067.643728,,1807.41890883515,1.00304537594633,0,0.959327444744187,0.959327444744187
8001068.815184,,1819.59444347912,0.997782921853925,0,0.953303779532659,0.953303779532659
8001069.98664,,1831.95851576526,0.992509194811913,0,0.947384894054302,0.947384894054302
8001071.158096,,1844.65004399273,0.987162998927005,0,0.941568965699108,0.941568965699108
8001072.329552,,1857.60954839501,0.981767719494279,0,0.935854203560793,0.935854203560793
8001073.501008,,1870.86568500183,0.976309115806151,0,0.930238847885314,0.930238847885314
8001074.672464,,1884.40253967121,0.970791146558573,0,0.924721169528986,0.924721169528986
8001075.84392,,1898.05994000076,0.965275168464259,0,0.919299469426029,0.919299469426029
8001077.015376,,1912.08981584604,0.959655760619717,0,0.913972078065368,0.913972078065368
8001078.186832,,1926.37526963924,0.953984478076246,0,0.908737354976542,0.908737354976542
8001079.358288,,1940.2689500369,0.948526124041787,0,0.903593688224548,0.903593688224548
8001080.529744,,1953.99241256047,0.943192096843177,0,0.898539493913479,0.898539493913479
8001081.7012,,1968.94842802379,0.937445987013308,0,0.89357321569879,0.89357321569879
8001082.872656,,1984.20007114449,0.931660223121428,0,0.888693324308055,0.888693324308055
8001084.044112,,1999.80896296068,0.925818175613048,0,0.883898317070052,0.883898317070052
8001085.215568,,2015.62801661861,0.919981086937555,0,0.879186717452044,0.879186717452044
8001086.387024,,2031.61284699472,0.914170027635318,0,0.874557074605112,0.874557074605112
8001087.55848,,2048.09654078157,0.90827101687399,0,0.870007962917389,0.870007962917389
8001088.729936,,2064.77072843403,0.902401795667445,0,0.865537981575072,0.865537981575072
8001089.901392,,2081.5815609368,0.89658553209052,0,0.861145754131067,0.861145754131067
8001091.072848,,2098.89215565566,0.890703592948959,0,0.856829928081138,0.856829928081138
8001092.244304,,2116.31798250889,0.884893432423996,0,0.852589174447427,0.852589174447427
8001093.41576,,2133.96071224405,0.879125222002398,0,0.848422187369222,0.848422187369222
8001094.587216,,2151.86954123695,0.873388329536935,0,0.844327683700843,0.844327683700843
8001095.758672,,2170.00177623292,0.867701885033106,0,0.840304402616516,0.840304402616516
8001096.930128,,2186.68844141862,0.862577615104642,0,0.836351105222132,0.836351105222132
8001098.101584,,2204.36683257826,0.85726062154183,0,0.832466574173749,0.832466574173749
8001099.27304,,2223.37122599971,0.851654912569698,0,0.828649613302732,0.828649613302732
8001100.444496,,2242.65469848572,0.846076579165025,0,0.824899047247419,0.824899047247419
8001101.615952,,2262.16916394948,0.840540085507964,0,0.82121372109119,0.82121372109119
8001102.787408,,2282.01026585556,0.835019161498994,0,0.817592500006829,0.817592500006829
8001103.958864,,2302.12357360874,0.829530070585453,0,0.814034268907077,0.814034268907077
8001105.13032,,2322.50023133265,0.824075753722747,0,0.810537932101263,0.810537932101263
8001106.301776,,2343.16556419012,0.818650011057944,0,0.807102412957907,0.807102412957907
8001107.473232,,2364.2120433915,0.813229954903727,0,0.803726653573185,0.803726653573185
8001108.644688,,2385.46712474297,0.807860724922584,0,0.800409614445177,0.800409614445177
8001109.816144,,2406.89160446951,0.802551320973634,0,0.797150274153764,0.797150274153764
8001110.9876,,2428.76448232933,0.797233366539553,0,0.793947629046106,0.793947629046106
8001112.159056,,2450.78352180209,0.791980892631955,0,0.790800692927582,0.790800692927582
8001113.330512,,2473.08417814279,0.7867609282735,0,0.787708496758114,0.787708496758114
8001114.501968,,2492.82622641101,0.782220767492113,0,0.784670088353762,0.784670088353762
8001115.673424,,2514.92036900232,0.777226787577218,0,0.781684532093528,0.781684532093528
8001116.84488,,2538.02455733564,0.772099631079594,0,0.778750908631236,0.778750908631236
8001118.016336,,2561.47806372893,0.766990056078988,0,0.775868314612449,0.775868314612449
8001119.187792,,2585.13631269634,0.761928012742379,0,0.773035862396289,0.773035862396289
8001120.359248,,2609.19487371021,0.756873678165692,0,0.770252679782108,0.770252679782108
8001121.530704,,2633.51065167001,0.751859554557098,0,0.767517909740909,0.767517909740909
8001122.70216,,2658.09009682597,0.746885894556918,0,0.764830710151443,0.764830710151443
8001123.873616,,2683.04783329705,0.741931724053392,0,0.762190253540889,0.762190253540889
8001125.045072,,2708.17613130309,0.737039900204126,0,0.759595726830053,0.759595726830053
8001126.216528,,2733.69384994946,0.732169437147548,0,0.757046331082994,0.757046331082994
8001127.387984,,2759.43085066843,0.727354647981394,0,0.754541281261005,0.754541281261005
8001128.55944,,2785.53292497663,0.72256989259121,0,0.752079805980879,0.752079805980879
8001129.730896,,2811.91008659617,0.717833553736733,0,0.749661147277372,0.749661147277372
8001130.902352,,2838.25015927684,0.713201273359561,0,0.747284560369803,0.747284560369803
8001132.073808,,2859.98554635189,0.709450855577128,0,0.744949313432715,0.744949313432715
8001133.245264,,2886.37486827925,0.704983507290274,0,0.74265468737052,0.74265468737052
8001134.41672,,2913.6497249707,0.7004637695554,0,0.740399975596068,0.740399975596068
8001135.588176,,2941.28050858505,0.695980557254003,0,0.738184483813068,0.738184483813068
8001136.759632,,2969.41076362554,0.69150906911423,0,0.736007529802289,0.736007529802289
8001137.931088,,2997.58688417489,0.687120889724069,0,0.733868443211488,0.733868443211488
8001139.102544,,3026.15311268631,0.682761336377876,0,0.731766565348985,0.731766565348985
8001140.274,,3054.97999475239,0.678450107602338,0,0.72970124898083,0.72970124898083
8001141.445456,,3084.07033253102,0.674186122582097,0,0.727671858131503,0.727671858131503
8001142.616912,,3113.48442528773,0.669960150336296,0,0.725677767888073,0.725677767888073
8001143.788368,,3143.22187649074,0.6657720950114,0,0.723718364207772,0.723718364207772
8001144.959824,,3173.04645894285,0.661654070122377,0,0.721793043728907,0.721793043728907
8001146.13128,,3203.16489787707,0.657576270018052,0,0.719901213585073,0.719901213585073
8001147.302736,,3233.05882051923,0.653606450803848,0,0.718042291222582,0.718042291222582
8001032.5,Error: Warning: Current field is 3999.853 Oe;
8001032.63,Error: but addenda was obtained at -0.046 Oe.
8006568.28,BEGIN:PULSE:PARAMS
8006568.28,ThResSigmaPerCycle=24.1271428619783
8006568.28,TempSigmaPerCycle=0.00182948590746068
8006568.28,NBinsOn=128
8006568.28,NBinsOff=128
8006568.28,Period=600
8006568.28,Iterations=1
8006568.28,HtrOverLoad=0
8006568.28,NCycRec=410
8006568.28,ThFreqHz=244.140625
8006568.28,NSampPerBin=410
8006568.28,PPMSTemp=0.4400718
8006568.28,EstTau=600
8006568.28,ThermOverload=0
8006568.28,ThResCorrFact=1
8006568.28,AvgHtrOnResistance=1111.97426574341
8006568.28,IsAddenda=0
8006568.28,AddendafromTbl=2.42856906842146E-8
8006568.28,AddendafromTblMinMidMax=5.85634912202866E-9|2.1421973534131E-8|6.3221982535191E-8
8006568.28,AddendaOffsetMinMidMax=0|0|0
8006568.28,AddendaErrfromTbl=7.63071356155165E-10
8006568.28,CondfromTbl=1.03229297101362E-7
8006568.28,TempMinMidMax=0.433789909009902|1.16569297832262|1.89759604763534
8006568.28,CondfromTblMinMidMax=8.40238823555968E-8|2.24354388810106E-7|3.71518850326767E-7
8006568.28,DisableTau2Fitting=1
8006568.28,HtrCurrOn=1.53495653580595E-5
8006568.28,StableStartTemperature=0.421763276409275
8006568.28,TimeStamp=8006568.28
8006568.28,PPMSStatus=5905
8006568.28,PuckTemp=0.440072
8006568.28,SystemTemp=0.4401
8006568.28,Field=3999.853
8006568.28,Pressure=9.19E-5
8006568.28,SampleTemp=1.2222035
8006568.28,TempRise=1.4018771
8006568.28,SampHC=7584.9496
8006568.28,SampHCErr=367.5
8006568.28,AddendaHC=0.024285691
8006568.28,AddendaHCErr=0.0007631
8006568.28,TotalHC=10.652674
8006568.28,TotalHCErr=0.5149
8006568.28,FitDeviation=563293.89
8006568.28,TimeConsttau1=57.692543
8006568.28,TimeConsttau2=0
8006568.28,SampleCoupling=100
8006568.28,DebyeTemp=18.706468
8006568.28,DebyeTempErr=0.2934
8006568.28,CalCorrection=1
8006568.28,ThermCondWire=1.8465E-7
8006568.28,AddendaOffset=0
8006568.28,END:PULSE:PARAMS
8006570.622912,,4251.33074083349,0.551759747239406,2.85513318560585E-7,0.557679454499598,0.557679454499598
8006572.965824,,3188.84243822453,0.659505469689898,2.82764656869477E-7,0.612651535656159,0.612651535656159
8006575.308736,,2691.91980170199,0.740193639829325,2.80501328074041E-7,0.665435906071379,0.665435906071379
8006577.651648,,2394.44563875907,0.805623342090589,2.78646208648318E-7,0.71611962954541,0.71611962954541
8006579.99456,,2194.00524479575,0.860363668816916,2.77095272718577E-7,0.764786305021212,0.764786305021212
8006582.337472,,2049.2442612424,0.907863852425789,2.75807439672675E-7,0.811516204474644,0.811516204474644
8006584.680384,,1939.68845758442,0.94875302067508,2.74708961761884E-7,0.856386405316977,0.856386405316977
8006587.023296,,1854.23607300713,0.983166306923168,2.73772053742846E-7,0.899470917528215,0.899470917528215
8006589.366208,,1786.24268532335,1.01238008619023,2.72977603522933E-7,0.940840805730922,0.940840805730922
8006591.70912,,1731.72131779642,1.03771051702353,2.72291697524739E-7,0.980564306405905,0.980564306405905
8006594.052032,,1688.59580671238,1.05944182408423,2.71741653576311E-7,1.0187069404431,1.0187069404431
8006596.394944,,1656.17648642966,1.07693232496746,2.71298024513195E-7,1.05533162121327,1.05533162121327
8006598.737856,,1619.12341424586,1.09811989864585,2.70781790272106E-7,1.09049875833887,1.09049875833887
8006601.080768,,1580.02409509909,1.12201879495948,2.70224371548806E-7,1.12426635733505,1.12426635733505
8006603.42368,,1543.43962067335,1.14598790266224,2.69674795015688E-7,1.1566901152854,1.1566901152854
8006605.766592,,1509.83024584898,1.16954247726712,2.69153055660962E-7,1.18782351270999,1.18782351270999
8006608.109504,,1479.16840605196,1.19245899382649,2.68656660602981E-7,1.21771790177749,1.21771790177749
8006610.452416,,1451.40132431128,1.21451173746386,2.68203008078242E-7,1.24642259100658,1.24642259100658
8006612.795328,,1426.23902130842,1.23566720738037,2.67776050161141E-7,1.27398492659665,1.27398492659665
8006615.13824,,1403.88540138547,1.25547930171492,2.67388355129981E-7,1.30045037052176,1.30045037052176
8006617.481152,,1384.1401987241,1.27384111162215,2.6703602785719E-7,1.32586257551664,1.32586257551664
8006619.824064,,1364.52285893335,1.29294509152026,2.66685829920806E-7,1.35026345707863,1.35026345707863
8006622.166976,,1341.14056586134,1.31692501644134,2.66245472764851E-7,1.37369326260405,1.37369326260405
8006624.509888,,1317.14145112867,1.34302318779552,2.65786315126474E-7,1.39619063777324,1.39619063777324
8006626.8528,,1293.62298906109,1.37019472842598,2.65331208420774E-7,1.41779269029366,1.41779269029366
8006629.195712,,1271.19795851509,1.39771251416426,2.64885501956285E-7,1.43853505110623,1.43853505110623
8006631.538624,,1249.95107461476,1.42536751107099,2.64459634674904E-7,1.45845193315583,1.45845193315583
8006633.881536,,1230.16768583021,1.45262500265054,2.64037195105788E-7,1.477576187823,1.477576187823
8006636.224448,,1211.63870567942,1.47958409506914,2.63646799452845E-7,1.49593935910975,1.49593935910975
8006638.56736,,1194.48824825093,1.50586896329995,2.63269543363582E-7,1.513571735669,1.513571735669
8006640.910272,,1178.65912624188,1.53135069848484,2.62917631571066E-7,1.5305024007634,1.5305024007634
8006643.253184,,1163.96070305846,1.55613732370414,2.62589869569505E-7,1.54675928023597,1.54675928023597
8006645.596096,,1150.52969898773,1.57979704373638,2.62291035382058E-7,1.56236918857166,1.56236918857166
8006647.939008,,1138.18051256473,1.6024554069724,2.6200362690216E-7,1.57735787312577,1.57735787312577
8006650.28192,,1126.80810438612,1.62413214650546,2.61732474088003E-7,1.59175005659227,1.59175005659227
8006652.624832,,1116.46187016853,1.64456425461936,2.61485522999837E-7,1.60556947778203,1.60556947778203
8006654.967744,,1106.92930542275,1.66401917554636,2.61254723707342E-7,1.61883893077812,1.61883893077812
8006657.310656,,1098.35918534289,1.68204891344718,2.61045425519054E-7,1.63158030253295,1.63158030253295
8006659.653568,,1090.37192736853,1.69933136376501,2.60844644676393E-7,1.64381460896916,1.64381460896916
8006661.99648,,1083.17838211441,1.71530723621318,2.60667442339311E-7,1.65556202964371,1.65556202964371
8006664.339392,,1076.57982737835,1.73031635799707,2.60502964085636E-7,1.66684194103261,1.66684194103261
8006666.682304,,1070.58354020789,1.74425950723906,2.60348924773859E-7,1.67767294849086,1.67767294849086
8006669.025216,,1065.19374717104,1.75704677354962,2.60214049489743E-7,1.68807291694062,1.68807291694062
8006671.368128,,1060.17162879863,1.76918446277793,2.60076940999152E-7,1.69805900033804,1.69805900033804
8006673.71104,,1055.72998360198,1.7801027718268,2.59961593287939E-7,1.70764766996737,1.70764766996737
8006676.053952,,1051.6070951391,1.79039525019852,2.59869356666996E-7,1.7168547416091,1.7168547416091
8006678.396864,,1047.91895513741,1.79973377851181,2.5977130332221E-7,1.7256954016269,1.7256954016269
8006680.739776,,1044.60187105457,1.80824075482088,2.59688830487718E-7,1.73418423201639,1.73418423201639
8006683.082688,,1041.54271787888,1.81617844851497,2.59606773133501E-7,1.74233523445696,1.74233523445696
8006685.4256,,1038.73216040794,1.82355031898151,2.59538218888205E-7,1.75016185340656,1.75016185340656
8006687.768512,,1036.19489650005,1.83027146374869,2.59467846916709E-7,1.75767699827723,1.75767699827723
8006690.111424,,1033.98304157646,1.83618245171635,2.59407706146973E-7,1.76489306472827,1.76489306472827
8006692.454336,,1031.92558502007,1.84172468795699,2.59349123428266E-7,1.77182195511188,1.77182195511188
8006694.797248,,1029.98360565236,1.84699506419728,2.59301447066765E-7,1.7784750981052,1.7784750981052
8006697.14016,,1028.35740604444,1.85143801651372,2.59257250352563E-7,1.78486346756104,1.78486346756104
8006699.483072,,1026.75807270798,1.85583409982282,2.59217883596552E-7,1.79099760060844,1.79099760060844
8006701.825984,,1025.44721182666,1.85945703626368,2.59180853917086E-7,1.79688761503281,1.79688761503281
8006704.168896,,1024.11477707209,1.86315799254312,2.59140240720252E-7,1.8025432259645,1.8025432259645
8006706.511808,,1022.95327942911,1.86639938529485,2.59112922892202E-7,1.80797376190315,1.80797376190315
8006708.85472,,1022.01612066575,1.86902511807304,2.59082696702231E-7,1.81318818010431,1.81318818010431
8006711.197632,,1021.0436424949,1.87175968449645,2.59059274001755E-7,1.81819508135381,1.81819508135381
8006713.540544,,1020.17969524009,1.87419754509279,2.59033462289701E-7,1.82300272415404,1.82300272415404
8006715.883456,,1019.36683432911,1.87649856951886,2.59017777909338E-7,1.82761903834575,1.82761903834575
8006718.226368,,1018.6476194642,1.87854044414892,2.59000068062636E-7,1.83205163818775,1.83205163818775
8006720.56928,,1018.18137388312,1.87986712116582,2.58982462086003E-7,1.83630783491597,1.83630783491597
8006722.912192,,1017.49593480957,1.88182178687919,2.58966310290332E-7,1.84039464880287,1.84039464880287
8006725.255104,,1017.05773158844,1.88307409082697,2.58949119793973E-7,1.8443188207368,1.8443188207368
8006727.598016,,1016.55194003185,1.88452215643963,2.58940498578277E-7,1.84808682334059,1.84808682334059
8006729.940928,,1016.13608249205,1.88571484123053,2.58924918067983E-7,1.85170487164765,1.85170487164765
8006732.28384,,1015.74216635316,1.88684634752035,2.5891790683835E-7,1.85517893335319,1.85517893335319
8006734.626752,,1015.47019588965,1.88762856567634,2.58909753037963E-7,1.85851473865749,1.85851473865749
8006736.969664,,1015.10171266437,1.8886896649464,2.58899262161031E-7,1.86171778971743,1.86171778971743
8006739.312576,,1014.78788080115,1.88959456892072,2.58890381270163E-7,1.86479336972185,1.86479336972185
8006741.655488,,1014.61580435384,1.89009119664179,2.58882175534742E-7,1.8677465516058,1.8677465516058
8006743.9984,,1014.33799020064,1.89089368396316,2.58877761056825E-7,1.87058220641796,1.87058220641796
8006746.341312,,1014.13890047081,1.8914692955591,2.58869243711197E-7,1.87330501135505,1.87330501135505
8006748.684224,,1013.99674077448,1.89188057900615,2.58867945335339E-7,1.8759194574765,1.8759194574765
8006751.027136,,1013.76707274388,1.89254550745311,2.58860570560467E-7,1.87842985711212,1.87842985711212
8006753.370048,,1013.64872883949,1.89288836215011,2.58857921873717E-7,1.88084035097499,1.88084035097499
8006755.71296,,1013.48290036228,1.89336904659709,2.58857194783236E-7,1.8831549149912,1.8831549149912
8006758.055872,,1013.34456295355,1.89377027719509,2.5885314385056E-7,1.88537736685788,1.88537736685788
8006760.398784,,1013.26686760763,1.89399571640725,2.58850391293741E-7,1.88751137234016,1.88751137234016
8006762.741696,,1013.21346583959,1.89415070486772,2.58844211024658E-7,1.88956045131762,1.88956045131762
8006765.084608,,1013.00188016954,1.89476510444206,2.58846184555962E-7,1.89152798359001,1.89152798359001
8006767.42752,,1012.94465611391,1.89493135664823,2.58839952351844E-7,1.89341721445202,1.89341721445202
8006769.770432,,1012.92874216651,1.89497759769882,2.58839173326329E-7,1.89523126004612,1.89523126004612
8006772.113344,,1012.83799958889,1.89524132181159,2.58834758848412E-7,1.89697311250239,1.89697311250239
8006774.456256,,1012.7576212911,1.89547500112175,2.58838290430746E-7,1.89864564487384,1.89864564487384
8006776.799168,,1012.64071074456,1.8958150174152,2.58833720147726E-7,1.90025161587527,1.90025161587527
8006779.14208,,1012.64986218313,1.8957883963576,2.5883003276029E-7,1.90179367443359,1.90179367443359
8006781.484992,,1012.57047621,1.89601935717671,2.5883039630553E-7,1.90327436405697,1.90327436405697
8006783.827904,,1012.56297864587,1.89604117378418,2.58824579581687E-7,1.90469612703021,1.90469612703021
8006786.170816,,1012.5658086088,1.89603293901049,2.58826605048025E-7,1.90606130844309,1.90606130844309
8006788.513728,,1012.47157451847,1.89630719444649,2.58825306672167E-7,1.90737216005841,1.90737216005841
8006790.85664,,1012.49252359472,1.8962462164384,2.58829461474912E-7,1.9086308440261,1.9086308440261
8006793.199552,,1012.34187400959,1.89668483251743,2.58820736389147E-7,1.90983943644953,1.90983943644953
8006795.542464,,1012.40806573997,1.89649208409712,2.58826449242922E-7,1.91099993080989,1.91099993080989
8006797.885376,,1012.44952285927,1.89637138712736,2.58824839256858E-7,1.91211424125428,1.91211424125428
8006800.228288,,1012.29707238865,1.89681532138603,2.58819697688461E-7,1.91318420575291,1.91318420575291
8006802.5712,,1012.36065467268,1.8966301387821,2.58823125400726E-7,1.91421158913079,1.91421158913079
8006804.914112,,1012.28453969567,1.89685182803718,2.58820944129285E-7,1.91519808597855,1.91519808597855
8006807.257024,,1012.36539577941,1.8966163321812,2.58821930894937E-7,1.91614532344765,1.91614532344765
8006809.599936,,1012.24510397846,1.8969667123483,2.58819853493564E-7,1.91705486393417,1.91705486393417
8006811.942848,,1012.30504773873,1.89679209079649,2.58823540881E-7,1.91792820765589,1.91792820765589
8006814.28576,,1012.34202102066,1.89668440437106,2.5881980155853E-7,1.91876679512679,1.91876679512679
8006816.628672,,1012.26969157847,1.89689508159564,2.58818814792878E-7,1.91957200953305,1.91957200953305
8006818.971584,,1012.26366412495,1.89691264067532,2.58824891191893E-7,1.92034517901454,1.92034517901454
8006821.314496,,1012.19497320654,1.89711277868774,2.58819489948324E-7,1.92108757885543,1.92108757885543
8006823.657408,,1012.23385763227,1.8969994784472,2.58817412546951E-7,1.92180043358775,1.92180043358775
[...]
8171244.424064,,1557.49106241662,1.16373206827629,2.06091213369403E-7,1.16208718179171,1.16208718179171
8171245.59552,,1547.22019626503,1.17042851676261,2.05972071349399E-7,1.17022475934593,1.17022475934593
8171246.766976,,1537.10468615331,1.17712861408318,2.05852080646513E-7,1.17822566306285,1.17822566306285
8171247.938432,,1527.28474110569,1.18373504913985,2.05735223541962E-7,1.1860921884337,1.1860921884337
8171249.109888,,1517.80120255174,1.1902129886733,2.05621108335953E-7,1.19382659239602,1.19382659239602
8171250.281344,,1508.41293423221,1.19672280745506,2.0550764596293E-7,1.20143109398116,1.20143109398116
8171251.4528,,1499.54222859849,1.20296446245219,2.05394771139595E-7,1.208907874951,1.208907874951
8171252.624256,,1490.66964610943,1.20929764436351,2.05287380113345E-7,1.21625908042384,1.21625908042384
8171253.795712,,1482.23894409721,1.21540087796311,2.05185146467687E-7,1.22348681948988,1.22348681948988
8171254.967168,,1474.05670072352,1.22140562997159,2.05078734690917E-7,1.23059316581631,1.23059316581631
8171256.138624,,1466.05788691605,1.2273549147585,2.04977676144634E-7,1.23758015824226,1.23758015824226
8171257.31008,,1458.42675171304,1.23310518495051,2.0487857609731E-7,1.24444980136375,1.24444980136375
8171258.481536,,1451.04700938721,1.23873657086536,2.04781891532036E-7,1.25120406610882,1.25120406610882
8171259.652992,,1443.6831542453,1.24442634247641,2.04690299064055E-7,1.25784489030298,1.25784489030298
8171260.824448,,1436.88859426666,1.2497399128645,2.04599751128852E-7,1.26437417922521,1.26437417922521
8171261.995904,,1430.14087636776,1.2550784619365,2.04511161692609E-7,1.27079380615456,1.27079380615456
8171263.16736,,1423.6115345528,1.26030374303149,2.04422702822962E-7,1.27710561290763,1.27710561290763
8171264.338816,,1417.48452707964,1.26526120413594,2.0433927076731E-7,1.28331141036697,1.28331141036697
8171265.510272,,1411.48924312981,1.27016370304245,2.04256752677839E-7,1.28941297900065,1.28941297900065
8171266.681728,,1405.71217665644,1.27493685107728,2.04178216869585E-7,1.29541206937307,1.29541206937307
8171267.853184,,1400.29633874946,1.27945598890645,2.04106078824596E-7,1.3013104026472,1.3013104026472
8171269.02464,,1395.25449731211,1.2837022884121,2.04037074377942E-7,1.30710967107841,1.30710967107841
8171270.196096,,1389.76755037889,1.28836708431577,2.03962977833994E-7,1.31281153849995,1.31281153849995
8171271.367552,,1383.65894137497,1.29361470691624,2.03877065012994E-7,1.31841764080036,1.31841764080036
8171272.539008,,1377.20816313845,1.29921944129298,2.03775745333517E-7,1.32392958639277,1.32392958639277
8171273.710464,,1370.33459019348,1.30526423351813,2.03686698914183E-7,1.32934895667636,1.32934895667636
8171274.88192,,1363.76868935127,1.31110982788968,2.03592625680854E-7,1.33467730649011,1.33467730649011
8171276.053376,,1356.96210163771,1.31724474642808,2.0349737734815E-7,1.33991616455886,1.33991616455886
8171277.224832,,1350.25292535973,1.32336806206669,2.03403499964717E-7,1.34506703393189,1.34506703393189
8171278.396288,,1343.87426066358,1.32926121817361,2.03312233913229E-7,1.35013139241419,1.35013139241419
8171279.567744,,1337.25387814736,1.33545279569827,2.032181606799E-7,1.35511069299043,1.35511069299043
8171280.7392,,1330.94999688439,1.34142080701407,2.03126241795426E-7,1.36000636424181,1.36000636424181
8171281.910656,,1324.77014668131,1.34734126686896,2.03038305192168E-7,1.36481981075598,1.36481981075598
8171283.082112,,1318.64612631594,1.35327773161179,2.02951608971585E-7,1.36955241352994,1.36955241352994
8171284.253568,,1312.72073540158,1.35908868391194,2.02862758402146E-7,1.37420553036632,1.37420553036632
8171285.425024,,1307.05731119728,1.36470543466776,2.0277573576507E-7,1.37878049626292,1.37878049626292
8171286.59648,,1301.30681147906,1.37047233856169,2.02696808257024E-7,1.38327862379573,1.38327862379573
8171287.767936,,1295.81859568589,1.37603717855913,2.02614290167552E-7,1.38770120349548,1.38770120349548
8171288.939392,,1290.56424664186,1.3814216083616,2.02531445661588E-7,1.39204950421795,1.39204950421795
8171290.110848,,1285.13172851349,1.3870479159226,2.0245310570323E-7,1.39632477350797,1.39632477350797
8171291.282304,,1280.25816962672,1.3921474390239,2.02376593677233E-7,1.40052823795737,1.40052823795737
8171292.45376,,1275.24347650534,1.39744689583993,2.02300081651236E-7,1.40466110355688,1.40466110355688
8171293.625216,,1270.44848119701,1.40256449650738,2.02221480559683E-7,1.40872455604214,1.40872455604214
8171294.796672,,1265.8407749039,1.40752924307783,2.02149342514694E-7,1.41271976123389,1.41271976123389
8171295.968128,,1261.32643555529,1.41243873987345,2.02075180687448E-7,1.41664786537245,1.41664786537245
8171297.139584,,1256.94432198707,1.41724797494819,2.02006502657287E-7,1.42050999544657,1.42050999544657
8171298.31104,,1252.76744651542,1.42187243786655,2.0194004425928E-7,1.4243072595168,1.4243072595168
8171299.482496,,1248.61671484561,1.42650760694917,2.01876850026204E-7,1.42804074703335,1.42804074703335
8171300.653952,,1244.56751840621,1.43106797535422,2.01815679575385E-7,1.4317115291487,1.4317115291487
8171301.825408,,1240.85245508641,1.43528597161909,2.01754900824359E-7,1.43532065902489,1.43532065902489
8171302.996864,,1237.10194299182,1.43957756567753,2.01695819439097E-7,1.43886917213568,1.43886917213568
8171304.16832,,1233.32037026309,1.4439390334136,2.0163693390373E-7,1.44235808656366,1.44235808656366
8171305.339776,,1229.97636917429,1.44782488333326,2.01583336315553E-7,1.44578840329231,1.44578840329231
8171306.511232,,1226.53477160783,1.45185294187595,2.01529804010675E-7,1.44916110649318,1.44916110649318
8171307.682688,,1223.2794056733,1.45569020818035,2.01477120388679E-7,1.45247716380829,1.45247716380829
8171308.854144,,1220.21680071252,1.45932462909861,2.01423392233905E-7,1.45573752662773,1.45573752662773
8171310.0256,,1217.08353611339,1.46306760454639,2.0136822784656E-7,1.45894313036259,1.45894313036259
8171311.197056,,1214.00179251506,1.46677364951733,2.01321354438143E-7,1.46209489471339,1.46209489471339
8171312.368512,,1211.25074554063,1.47010282940018,2.012756561291E-7,1.4651937239339,1.4651937239339
8171313.539968,,1208.45357022019,1.47350816141496,2.01229957820058E-7,1.4682405070906,1.4682405070906
8171314.711424,,1205.74796429265,1.47682169447823,2.01185304043793E-7,1.47123611831774,1.47123611831774
8171315.88288,,1203.24275893312,1.47990720490021,2.0114300046628E-7,1.47418141706813,1.47418141706813
8171317.054336,,1200.61970820593,1.48315594904628,2.0109762857373E-7,1.47707724835975,1.47707724835975
8171318.225792,,1198.23581114434,1.48612467780666,2.01058197461356E-7,1.47992444301815,1.47992444301815
8171319.397248,,1195.97766339049,1.48895113573072,2.01018374649191E-7,1.48272381791485,1.48272381791485
8171320.568704,,1193.62953231867,1.49190512166818,2.00979857502998E-7,1.48547617620168,1.48547617620168
8171321.74016,,1191.55314875235,1.49452999315156,2.00946367170799E-7,1.48818230754122,1.48818230754122
8171322.911616,,1189.49783354808,1.49714009948873,2.00909547390371E-7,1.49084298833336,1.49084298833336
8171324.083072,,1187.28734734602,1.49996053405008,2.00873967992616E-7,1.49345898193804,1.49345898193804
8171325.254528,,1185.52180803234,1.50222319253418,2.00842501442676E-7,1.49603103889425,1.49603103889425
8171326.425984,,1183.54722404225,1.50476429003456,2.00808945827179E-7,1.49855989713543,1.49855989713543
8171327.59744,,1181.65389995799,1.50721132547638,2.00777936260328E-7,1.50104628220108,1.50104628220108
8171328.768896,,1180.00697261485,1.50934832506676,2.0074444592813E-7,1.503490907445,1.503490907445
8171329.940352,,1178.37886669427,1.51146864817687,2.00713697494474E-7,1.50589447423995,1.50589447423995
8171331.111808,,1176.67076972781,1.51370146995354,2.0068719247523E-7,1.50825767217883,1.50825767217883
8171332.283264,,1175.04007321817,1.51584111177482,2.00659185940117E-7,1.51058117927257,1.51058117927257
8171333.45472,,1173.58865604532,1.51775212742607,2.00633464320455E-7,1.51286566214461,1.51286566214461
8171334.626176,,1172.19243428021,1.51959637152631,2.00608591383677E-7,1.51511177622222,1.51511177622222
8171335.797632,,1170.75045425323,1.52150716135711,2.00587374311621E-7,1.5173201659245,1.5173201659245
8171336.969088,,1169.25119048652,1.5235004684906,2.00562240241648E-7,1.51949146484726,1.51949146484726
8171338.140544,,1167.95163998869,1.52523373011893,2.00539456370425E-7,1.52162629594484,1.52162629594484
8171339.312,,1166.87080922436,1.52667916865443,2.00518826848057E-7,1.5237252717088,1.5237252717088
8171340.483456,,1165.53131607276,1.52847545197045,2.00496826376418E-7,1.52578899434366,1.52578899434366
8171341.654912,,1164.35711836393,1.53005457354365,2.00476914970336E-7,1.52781805593969,1.52781805593969
8171342.826368,,1163.19016373065,1.53162813913248,2.00455763181579E-7,1.52981303864276,1.52981303864276
8171343.997824,,1172.90817702913,1.51865023516312,0,1.52321984676456,1.52321984676456
8171345.16928,,1190.68448194513,1.49563169376892,0,1.50829033108901,1.50829033108901
8171346.340736,,1207.99268327872,1.47407123348546,0,1.49361156254093,1.49361156254093
8171347.512192,,1224.9905690513,1.45366986118846,0,1.47917932972302,1.47917932972302
8171348.683648,,1241.83846500422,1.43416328990467,0,1.46498949197007,1.46498949197007
8171349.855104,,1258.37604539614,1.41567194841467,0,1.45103797816099,1.45103797816099
8171351.02656,,1274.27734539338,1.39847404650973,0,1.43732078555076,1.43732078555076
8171352.198016,,1289.98038602378,1.38202338803558,0,1.42383397862207,1.42383397862207
8171353.369472,,1305.48810152595,1.36627269754348,0,1.41057368795617,1.41057368795617
8171354.540928,,1320.42229233169,1.35154876711895,0,1.39753610912273,1.39753610912273
8171355.712384,,1334.96985093749,1.33760689688742,0,1.38471750158834,1.38471750158834
8171356.88384,,1349.05853163007,1.32446620247263,0,1.37211418764332,1.37211418764332
8171358.055296,,1362.6913479518,1.31207573249073,0,1.35972255134658,1.35972255134658
8171359.226752,,1375.47532340301,1.30073621731885,0,1.34753903748822,1.34753903748822
8171360.398208,,1387.45280618445,1.2903487913289,0,1.33556015056946,1.33556015056946
8171361.569664,,1397.41777135028,1.28187568385457,0,1.32378245379982,1.32378245379982
8171362.74112,,1406.1435890387,1.27457872616543,0,1.31220256811109,1.31220256811109
8171363.912576,,1415.30013181026,1.26704148393388,0,1.30081717118783,1.30081717118783
8171365.084032,,1424.81089798392,1.25933948491323,0,1.28962299651422,1.28962299651422
8171366.255488,,1434.44511365668,1.2516659565011,0,1.27861683243685,1.27861683243685
8171367.426944,,1444.21858670871,1.24401022988931,0,1.26779552124331,1.26779552124331
8171368.5984,,1454.33444047,1.23621931920837,0,1.25715595825622,1.25715595825622
8171369.769856,,1464.51450383157,1.22851198269192,0,1.24669509094249,1.24669509094249
8171370.941312,,1474.5725187269,1.22102468304902,0,1.23640991803752,1.23640991803752
8171372.112768,,1484.82115339482,1.2135225817942,0,1.22629748868415,1.22629748868415
8171373.284224,,1495.32382439813,1.20596415273421,0,1.21635490158602,1.21635490158602
8171374.45568,,1505.68631281178,1.19863184982291,0,1.20657930417521,1.20657930417521
8171375.627136,,1516.08731641177,1.19139413115383,0,1.1969678917938,1.1969678917938
8171376.798592,,1526.69117899592,1.18413765078505,0,1.1875179068892,1.1875179068892
8171377.970048,,1537.27257218516,1.17701654934461,0,1.17822663822302,1.17822663822302
8171379.141504,,1547.73553844593,1.17008998531232,0,1.16909142009318,1.16909142009318
8171380.31296,,1558.28835585176,1.16321665891113,0,1.16010963156915,1.16010963156915
8171381.484416,,1568.81103783383,1.15647283365635,0,1.15127869573993,1.15127869573993
8171382.655872,,1579.20252498421,1.14991807211989,0,1.14259607897477,1.14259607897477
8171383.827328,,1589.5738954175,1.14347745774402,0,1.13405929019628,1.13405929019628
8171384.998784,,1599.87061459053,1.13718103476142,0,1.12566588016567,1.12566588016567
8171386.17024,,1609.83692792005,1.13117728471797,0,1.11741344078009,1.11741344078009
8171387.341696,,1619.27404734757,1.12557261943283,0,1.10929960438174,1.10929960438174
8171388.513152,,1628.40172355531,1.12022441407863,0,1.10132204307856,1.10132204307856
8171389.684608,,1636.96909235775,1.11526819350197,0,1.09347846807638,1.09347846807638
8171390.856064,,1644.3818779114,1.11102871323982,0,1.08576662902221,1.08576662902221
8171392.02752,,1651.06982721983,1.10724197498665,0,1.07818431335865,1.07818431335865
8171393.198976,,1657.89462836057,1.103414518406,0,1.07072934568904,1.07072934568904
8171394.370432,,1665.24426169722,1.09933361511408,0,1.06339958715343,1.06339958715343
8171395.541888,,1672.92033569005,1.09511598904565,0,1.05619293481481,1.05619293481481
8171396.713344,,1681.32010924104,1.09055196353286,0,1.04910732105586,1.04910732105586
8171397.8848,,1690.16821330694,1.0858011868559,0,1.04214071298571,1.04214071298571
8171399.056256,,1699.55502772445,1.08082368812018,0,1.03529111185669,1.03529111185669
8171400.227712,,1709.09442255068,1.07582990684539,0,1.0285565524909,1.0285565524909
8171401.399168,,1719.08198928433,1.07066987097396,0,1.02193510271636,1.02193510271636
8171402.570624,,1729.50271308267,1.06535899653656,0,1.01542486281271,1.01542486281271
8171403.74208,,1740.2714481563,1.05994730196057,0,1.00902396496613,1.00902396496613
8171404.913536,,1751.19339806862,1.05453621836558,0,1.00273057273346,1.00273057273346
8171406.084992,,1762.57893124981,1.04897676317115,0,0.996542880515362,0.996542880515362
8171407.256448,,1774.29886189642,1.04333874070961,0,0.99045911303823,0.99045911303823
8171408.427904,,1786.21041682974,1.03769455466527,0,0.984477524844889,0.984477524844889
8171409.59936,,1798.34481529139,1.0320318469408,0,0.978596399793806,0.978596399793806
8171410.770816,,1810.94004782536,1.02624481129932,0,0.972814050566729,0.972814050566729
8171411.942272,,1823.74342625993,1.02045456386036,0,0.967128818184578,0.967128818184578
8171413.113728,,1836.75019237032,1.01466539882917,0,0.961539071531489,0.961539071531489
8171414.285184,,1850.09471313807,1.00882095742123,0,0.956043206886831,0.956043206886831
8171415.45664,,1863.81780355817,1.00290858647669,0,0.950639647465098,0.950639647465098
8171416.628096,,1877.58049298248,0.997076280116302,0,0.945326842963522,0.945326842963522
8171417.799552,,1891.74067922004,0.991174422502402,0,0.94010326911728,0.94010326911728
8171418.971008,,1906.3143551931,0.985202233151466,0,0.934967427262184,0.934967427262184
8171420.142464,,1921.12618031763,0.979235665712997,0,0.929917843904704,0.929917843904704
8171421.31392,,1936.32831204902,0.973217160426054,0,0.924953070299215,0.924953070299215
8171422.485376,,1951.63967147426,0.967260297865401,0,0.920071682032349,0.920071682032349
8171423.656832,,1967.29740323068,0.961274560673386,0,0.915272278614328,0.915272278614328
8171424.828288,,1983.40632043689,0.955224468426215,0,0.91055348307715,0.91055348307715
8171425.999744,,1999.54180439826,0.949269859765183,0,0.905913941579539,0.905913941579539
8171427.1712,,2016.20230559763,0.943229406634196,0,0.901352323018516,0.901352323018516
8171428.342656,,2033.08863743313,0.937216178234734,0,0.896867318647508,0.896867318647508
8171429.514112,,2050.07655736821,0.931274833587571,0,0.892457641700854,0.892457641700854
8171430.685568,,2067.75859656393,0.925202932922991,0,0.888122027024636,0.888122027024636
8171431.857024,,2085.50690725734,0.919220434748646,0,0.883859230713694,0.883859230713694
8171433.02848,,2103.47512724046,0.913275327400422,0,0.879668029754751,0.879668029754751
8171434.199936,,2121.97740508871,0.907267730005237,0,0.875547221675518,0.875547221675518
8171435.371392,,2140.67490232685,0.901311389184686,0,0.871495624199708,0.871495624199708
8171436.542848,,2159.66206971725,0.895377588742072,0,0.867512074907831,0.867512074907831
8171437.714304,,2179.06005695035,0.88943170187588,0,0.863595430903692,0.863595430903692
8171438.88576,,2198.76249126719,0.883509590889849,0,0.85974456848649,0.85974456848649
8171440.057216,,2218.59374130332,0.87766470749507,0,0.855958382828426,0.855958382828426
8171441.228672,,2238.97007242537,0.871777037014675,0,0.852235787657719,0.852235787657719
8171442.400128,,2259.59576096176,0.865935646238415,0,0.848575714946955,0.848575714946955
8171443.571584,,2280.51772829597,0.86012861134167,0,0.84497711460666,0.84497711460666
8171444.74304,,2301.79714405133,0.854339229849722,0,0.841438954184032,0.841438954184032
8171445.914496,,2323.45806369766,0.848561149757017,0,0.837960218566721,0.837960218566721
8171447.085952,,2345.34914925162,0.842836266425528,0,0.834539909691591,0.834539909691591
8171448.257408,,2367.72382905321,0.8371005348176,0,0.831177046258371,0.831177046258371
8171449.428864,,2390.41183795816,0.831400377313045,0,0.827870663448117,0.827870663448117
8171450.60032,,2413.25356395888,0.825776063619004,0,0.824619812646403,0.824619812646403
8171451.771776,,2436.70415769249,0.820117818648811,0,0.821423561171155,0.821423561171155
8171452.943232,,2460.37579740285,0.814521922012609,0,0.818280992005066,0.818280992005066
8171454.114688,,2484.36214081486,0.808966681291294,0,0.815191203532496,0.815191203532496
8171455.286144,,2508.82806041799,0.803416137594945,0,0.812153309280798,0.812153309280798
8171456.4576,,2533.5922414126,0.797913436847531,0,0.809166437665983,0.809166437665983
8171457.629056,,2558.67789336192,0.792454235128906,0,0.806229731742663,0.806229731742663
8171458.800512,,2584.07082089528,0.787042431449038,0,0.803342348958183,0.803342348958183
8171459.971968,,2609.9991015883,0.781631575629697,0,0.800503460910896,0.800503460910896
8171461.143424,,2636.3306418335,0.776251922112639,0,0.797712253112489,0.797712253112489
8171462.31488,,2662.7168223602,0.77097416402854,0,0.794967924754301,0.794967924754301
8171463.486336,,2689.7544302972,0.765677532720143,0,0.79226968847757,0.79226968847757
8171464.657792,,2717.29897421796,0.760391283834681,0,0.789616770147539,0.789616770147539
8171465.829248,,2744.91468003412,0.755199623808137,0,0.787008408631346,0.787008408631346
8171467.000704,,2772.99989046556,0.750027965239777,0,0.78444385557966,0.78444385557966
8171468.17216,,2801.65074808793,0.744861695827205,0,0.781922375211973,0.781922375211973
8171469.343616,,2830.58947831096,0.739752859922124,0,0.779443244105502,0.779443244105502
8171470.515072,,2859.78972585616,0.734706274780649,0,0.777005750987634,0.777005750987634
8171471.686528,,2889.49651286637,0.729680914886925,0,0.774609196531865,0.774609196531865
8171472.857984,,2919.64785024623,0.724689513208561,0,0.772252893157153,0.772252893157153
8171474.02944,,2950.14188555033,0.719750202743319,0,0.769936164830653,0.769936164830653
8171475.200896,,2980.93415581134,0.714870612342364,0,0.767658346873761,0.767658346873761
8171476.372352,,3012.40883481306,0.709991996903249,0,0.765418785771411,0.765418785771411
8171477.543808,,3044.10582865147,0.705187335268556,0,0.763216838984582,0.763216838984582
8171478.715264,,3076.10843269523,0.700443659550022,0,0.761051874765952,0.761051874765952
8171479.88672,,3108.67335317255,0.695720890140584,0,0.758923271978642,0.758923271978642
8171481.058176,,3141.66817926094,0.691037086723081,0,0.756830419918016,0.756830419918016
8171482.229632,,3175.01767813935,0.686403370381837,0,0.754772718136462,0.754772718136462
8171483.401088,,3208.80556812973,0.681808535098319,0,0.752749576271126,0.752749576271126
8171484.572544,,3242.99677054145,0.677257942760642,0,0.750760413874529,0.750760413874529
8171485.744,,3277.59374379066,0.672751663048015,0,0.748804660248039,0.748804660248039
8171486.915456,,3312.71549636664,0.668275050428381,0,0.746881754278134,0.746881754278134
8171488.086912,,3348.05462051243,0.663867313667237,0,0.744991144275413,0.744991144275413
8171489.258368,,3383.94939957704,0.659486364646882,0,0.743132287816319,0.743132287816319
8171490.429824,,3420.38783226015,0.655135031215352,0,0.741304651587515,0.741304651587515
8171491.60128,,3457.06565652008,0.650849708614337,0,0.739507711232869,0.739507711232869
8171492.772736,,3494.13074740993,0.646612546802977,0,0.737740951203021,0.737740951203021