File: rawhc/NBMPO_HIIaplane.raw
[Header]
TITLE,
BYAPP,HeatCapacity,3.9.6,4.0
INFO,PPMS Heat Capacity Option 3.9.6 Build 3,APPNAME
DATATYPE,TIME,1
DATATYPE,COMMENT,2
STARTUPAXIS, X, 1, LINEAR, AUTO
STARTUPAXIS, Y1, 4, LINEAR, AUTO
[Data]
Time Stamp (Seconds),Comment (),Therm Res (Ohms),Platform Temp (Kelvin),Heater Power (Watts),Platform Temp Fit (Kelvin),Sample Temp Fit (Kelvin)
16133723.13,CALFILE: C:\QdPpms\HEATCA~3\TempCal\He3\He3Puck977.cal|Addenda #1 measured on 8/15/2023 from 0.45343 to 21.302 K
16133723.42,BEGIN:PULSE:PARAMS
16133723.42,ThResSigmaPerCycle=51.2467164835504
16133723.42,TempSigmaPerCycle=0.001891111191478
16133723.42,NBinsOn=128
16133723.42,NBinsOff=128
16133723.42,Period=300
16133723.42,Iterations=1
16133723.42,HtrOverLoad=0
16133723.42,NCycRec=285
16133723.42,ThFreqHz=244.140625
16133723.42,NSampPerBin=285
16133723.42,PPMSTemp=0.4498
16133723.42,EstTau=300
16133723.42,ThermOverload=0
16133723.42,ThResCorrFact=1
16133723.42,AvgHtrOnResistance=2268.19269074564
16133723.42,IsAddenda=0
16133723.42,AddendafromTbl=4.19251457305724E-8
16133723.42,AddendafromTblMinMidMax=5.22568845340317E-8|3.88117406681983E-8|4.90765192120521E-8
16133723.42,AddendaOffsetMinMidMax=0|0|0
16133723.42,AddendaErrfromTbl=1.61951269496288E-9
16133723.42,CondfromTbl=7.97147188598619E-8
16133723.42,TempMinMidMax=0.508770335517221|0.91602483717128|1.32327933882534
16133723.42,CondfromTblMinMidMax=9.15183661909054E-8|1.63876806877163E-7|2.54803486765462E-7
16133723.42,DisableTau2Fitting=1
16133723.42,HtrCurrOn=1.04151831270392E-5
16133723.42,StableStartTemperature=0.472360952256489
16133723.42,TimeStamp=16133723.42
16133723.42,PPMSStatus=5905
16133723.42,PuckTemp=
16133723.42,SystemTemp=0.4498
16133723.42,Field=-0.062
16133723.42,Pressure=9.09E-5
16133723.42,SampleTemp=1.0206804
16133723.42,TempRise=0.63974894
16133723.42,SampHC=16581.86
16133723.42,SampHCErr=847
16133723.42,AddendaHC=0.041925146
16133723.42,AddendaHCErr=0.00162
16133723.42,TotalHC=38.767399
16133723.42,TotalHCErr=1.978
16133723.42,FitDeviation=84802.086
16133723.42,TimeConsttau1=179.68557
16133723.42,TimeConsttau2=
16133723.42,SampleCoupling=
16133723.42,DebyeTemp=12.005994
16133723.42,DebyeTempErr=0.2026
16133723.42,CalCorrection=1
16133723.42,ThermCondWire=2.1575131E-7
16133723.42,AddendaOffset=0
16133723.42,END:PULSE:PARAMS
16133724.591456,,6470.46603025419,0.508770335517221,2.63471918979411E-7,0.704526611069366,0.704526611069366
16133725.762912,,5712.88856001009,0.540802527465512,2.62875047812812E-7,0.711909867695561,0.711909867695561
16133726.934368,,5170.16182695833,0.569098762452605,2.62285884098198E-7,0.719245145915581,0.719245145915581
16133728.105824,,4758.33381603071,0.594361888572854,2.61704022180203E-7,0.726532757506137,0.726532757506137
16133729.27728,,4433.1995633233,0.617331906223424,2.61130374783402E-7,0.733773012217927,0.733773012217927
16133730.448736,,4168.83555861769,0.6384167770629,2.60567426546924E-7,0.74096621778881,0.74096621778881
16133731.620192,,3948.98175436036,0.658020201802215,2.60017459282211E-7,0.748112679956875,0.748112679956875
16133732.791648,,3762.53568528517,0.676452425845941,2.59471751398858E-7,0.755212702473447,0.755212702473447
16133733.963104,,3602.13129449168,0.693906263201754,2.58935576416646E-7,0.762266587115988,0.762266587115988
16133735.13456,,3462.47765602694,0.710532221592577,2.58418010874425E-7,0.769274633700932,0.769274633700932
16133736.306016,,3339.64121135051,0.726442089273919,2.57916367305386E-7,0.776237140096423,0.776237140096423
16133737.477472,,3230.54494793092,0.741683953039795,2.5742978369187E-7,0.783154402234975,0.783154402234975
16133738.648928,,3132.86636189246,0.756296365996451,2.56952479444891E-7,0.790026714126054,0.790026714126054
16133739.820384,,3045.00211902536,0.770282603199252,2.56492770499483E-7,0.796854367868574,0.796854367868574
16133740.99184,,2965.2198394396,0.783723775479258,2.5604330435211E-7,0.803637653663308,0.803637653663308
16133742.163296,,2892.57664599055,0.796617193857582,2.55602661208982E-7,0.810376859825228,0.810376859825228
16133743.334752,,2826.05786926164,0.809025641479461,2.55174339847648E-7,0.817072272795754,0.817072272795754
16133744.506208,,2765.07075872065,0.820987237444212,2.54759658648052E-7,0.823724177154937,0.823724177154937
16133745.677664,,2708.74101927136,0.832562810703212,2.54358566903272E-7,0.830332855633544,0.830332855633544
16133746.84912,,2656.58679901306,0.843755495454697,2.53966906645791E-7,0.836898589125084,0.836898589125084
16133748.020576,,2608.14943394065,0.854579651643091,2.53594160069827E-7,0.843421656697743,0.843421656697743
16133749.192032,,2562.99893981479,0.865058413570867,2.5322602782367E-7,0.849902335606246,0.849902335606246
16133750.363488,,2520.95618085561,0.875167872238169,2.5286884827244E-7,0.856340901303641,0.856340901303641
16133751.534944,,2481.52099892894,0.884971136227987,2.5252485252066E-7,0.862737627453009,0.862737627453009
16133752.7064,,2444.65537543695,0.894427009477219,2.52186130288659E-7,0.869092785939092,0.869092785939092
16133753.877856,,2409.7992988214,0.903637744058494,2.51858817113873E-7,0.875406646879853,0.875406646879853
16133755.049312,,2377.05926360544,0.912556489108311,2.51538856442627E-7,0.881679478637953,0.881679478637953
16133756.220768,,2346.16462937286,0.921224210370003,2.51224219998081E-7,0.887911547832161,0.887911547832161
16133757.392224,,2317.04623039821,0.929626383032185,2.50924491388297E-7,0.894103119348684,0.894103119348684
16133758.56368,,2289.44268550508,0.937808100289489,2.50632723765103E-7,0.900254456352429,0.900254456352429
16133759.735136,,2263.30480664018,0.94575696995812,2.50350032680761E-7,0.906365820298182,0.906365820298182
16133760.906592,,2238.43475382862,0.953508788398869,2.50079207015923E-7,0.912437470941728,0.912437470941728
16133762.078048,,2214.86412522114,0.961031031231031,2.49815632440782E-7,0.918469666350887,0.918469666350887
16133763.249504,,2192.45137914335,0.968347287401076,2.49555759470871E-7,0.924462662916484,0.924462662916484
16133764.42096,,2171.03886974157,0.97549060659053,2.49299689520032E-7,0.930416715363248,0.930416715363248
16133765.592416,,2150.64442569533,0.982438035003521,2.49058628817797E-7,0.936332076760636,0.936332076760636
16133766.763872,,2131.2915267388,0.989164092588663,2.48818987909348E-7,0.942208998533593,0.942208998533593
16133767.935328,,2112.72096721896,0.995743815291856,2.48582845778446E-7,0.948047730473234,0.948047730473234
16133769.106784,,2094.89701018446,1.00217777017177,2.48355171703343E-7,0.953848520747466,0.953848520747466
16133770.27824,,2077.9089582175,1.00842105745638,2.48129221663553E-7,0.959611615911531,0.959611615911531
16133771.449696,,2061.64928209478,1.01450072316231,2.47911384731117E-7,0.96533726091849,0.96533726091849
16133772.621152,,2046.10033885219,1.02041213131209,2.47699632629195E-7,0.971025699129632,0.971025699129632
16133773.792608,,2031.02099029317,1.02623816302222,2.47494979496208E-7,0.976677172324818,0.976677172324818
16133774.964064,,2016.84015942618,1.03180260510939,2.47298845125941E-7,0.982291920712759,0.982291920712759
16133776.13552,,2003.01229396429,1.03731013519006,2.47107375792403E-7,0.987870182941222,0.987870182941222
16133777.306976,,1989.76155240928,1.04266496317295,2.46919658771016E-7,0.993412196107178,0.993412196107178
16133778.478432,,1976.99242397806,1.04789806002254,2.46736302544831E-7,0.998918195766878,0.998918195766878
16133779.649888,,1964.9191181325,1.05291307741068,2.46559386097607E-7,1.00438841594586,1.00438841594586
16133780.821344,,1953.20944306282,1.05784050926029,2.46388909429346E-7,1.00982308914891,1.00982308914891
16133781.9928,,1941.96302182196,1.06263289816016,2.46221475176342E-7,1.01522244636993,1.01522244636993
16133783.164256,,1931.02979635734,1.06734907300937,2.46059517270801E-7,1.02058671710175,1.02058671710175
16133784.335712,,1920.71158074357,1.07185259941405,2.45900753901281E-7,1.02591612934591,1.02591612934591
16133785.507168,,1910.64240949674,1.07629752022148,2.45744475170888E-7,1.03121090962233,1.03121090962233
16133786.678624,,1900.94488131926,1.08062590030662,2.45595650357875E-7,1.03647128297893,1.03647128297893
16133787.85008,,1891.70983757817,1.08479186217201,2.45451693409275E-7,1.04169747300123,1.04169747300123
16133789.021536,,1882.76745479497,1.08886732194816,2.45310626755169E-7,1.0468897018218,1.0468897018218
16133790.192992,,1874.27275227678,1.09277712507678,2.45175087155448E-7,1.05204819012977,1.05204819012977
16133791.364448,,1866.00902666905,1.09661698792116,2.4504395905785E-7,1.05717315718013,1.05717315718013
16133792.535904,,1858.13851364919,1.100307934465,2.44914402874801E-7,1.06226482080313,1.06226482080313
16133793.70736,,1850.55562074033,1.10389622065244,2.44790880815347E-7,1.06732339741348,1.06732339741348
16133794.878816,,1843.32436669792,1.10734840416478,2.4467141530957E-7,1.07234910201956,1.07234910201956
16133796.050272,,1836.56345020073,1.11060317629944,2.44561178463406E-7,1.07734214823259,1.07734214823259
16133797.221728,,1830.22370972625,1.11367932047575,2.44453223428686E-7,1.08230274827568,1.08230274827568
16133798.393184,,1824.22236926244,1.11661305324984,2.44350592620667E-7,1.08723111299284,1.08723111299284
16133799.56464,,1818.55831451685,1.11940156957545,2.44254553712372E-7,1.09212745185797,1.09212745185797
16133800.736096,,1813.27433962644,1.12202037392867,2.44165055996881E-7,1.09699197298376,1.09699197298376
16133801.907552,,1808.18128017915,1.12456063022735,2.44076927368255E-7,1.10182488313052,1.10182488313052
16133803.079008,,1803.12106582894,1.12710028778886,2.43989508636523E-7,1.10662638771497,1.10662638771497
16133804.250464,,1798.14047032874,1.1296155026437,2.43903458991657E-7,1.11139669081897,1.11139669081897
16133805.42192,,1793.11469292199,1.13216929481873,2.43814671173059E-7,1.11613599519823,1.11613599519823
16133806.593376,,1787.6668905078,1.13495560001123,2.43719392868579E-7,1.12084450229087,1.12084450229087
16133807.764832,,1781.29480902093,1.13823874840397,2.43611792782305E-7,1.12552241222602,1.12552241222602
16133808.936288,,1774.59077450123,1.14172135108068,2.43492885052658E-7,1.13016992383232,1.13016992383232
16133810.107744,,1767.80107211525,1.14527855652834,2.43370174303939E-7,1.13478723464637,1.13478723464637
16133811.2792,,1760.77755402608,1.14899057876718,2.43248832642086E-7,1.1393745409211,1.1393745409211
16133812.450656,,1753.8850448944,1.15266576353705,2.43123282305794E-7,1.14393203763417,1.14393203763417
16133813.622112,,1747.08743633804,1.1563222297808,2.42996971365687E-7,1.14845991849619,1.14845991849619
16133814.793568,,1740.29855640602,1.16000604820306,2.428738549616E-7,1.15295837595902,1.15295837595902
16133815.965024,,1733.3781899626,1.16379464524381,2.42752411885905E-7,1.15742760122388,1.15742760122388
16133817.13648,,1726.73066598958,1.16746610400379,2.42630512447922E-7,1.16186778424954,1.16186778424954
16133818.307936,,1720.12641370745,1.17114537899349,2.42511503304433E-7,1.16627911376035,1.16627911376035
16133819.479392,,1713.53802682762,1.17484775130393,2.42388336193425E-7,1.17066177725429,1.17066177725429
16133820.650848,,1706.99447695431,1.17855693876275,2.42267603014624E-7,1.17501596101091,1.17501596101091
16133821.822304,,1700.6790121372,1.18216750666418,2.42141647022963E-7,1.17934185009928,1.17934185009928
16133822.99376,,1694.33115324615,1.18582736627371,2.42018784153482E-7,1.18363962838584,1.18363962838584
16133824.165216,,1688.11899925942,1.18943925572659,2.41897898853917E-7,1.18790947854221,1.18790947854221
16133825.336672,,1681.83141828482,1.19312590290665,2.41776557192064E-7,1.19215158205297,1.19215158205297
16133826.508128,,1675.77396523594,1.19670741311841,2.41657750876259E-7,1.19636611922334,1.19636611922334
16133827.679584,,1669.83757210464,1.20024609009661,2.41544218080234E-7,1.2005532691869,1.2005532691869
16133828.85104,,1663.89942794232,1.20381464787847,2.41427287920504E-7,1.20471320991314,1.20471320991314
16133830.022496,,1658.0501884006,1.20735833878536,2.41312284623771E-7,1.20884611821509,1.20884611821509
16133831.193952,,1652.43192576935,1.21078912334948,2.41195253050199E-7,1.21295216975677,1.21295216975677
16133832.365408,,1646.71658703938,1.21430670432126,2.41078221476627E-7,1.21703153906071,1.21703153906071
16133833.536864,,1641.31659307829,1.21765601471858,2.40967122612808E-7,1.22108439951532,1.22108439951532
16133834.70832,,1635.79293918385,1.22110829216309,2.40859471819614E-7,1.22511092338231,1.22511092338231
16133835.879776,,1630.30356304824,1.22456578532322,2.40750502646474E-7,1.22911128180398,1.22911128180398
16133837.051232,,1625.08986817573,1.22787452699573,2.40644018112462E-7,1.2330856448105,1.2330856448105
16133838.222688,,1619.8960183215,1.23119506891122,2.40538547716869E-7,1.23703418132712,1.23703418132712
16133839.394144,,1614.75658308285,1.23450506885639,2.40433178735118E-7,1.2409570591814,1.2409570591814
16133840.5656,,1609.85091048585,1.23768727307923,2.40328671771023E-7,1.24485444511029,1.24485444511029
16133841.737056,,1604.78525732715,1.24099684615538,2.40221933702406E-7,1.24872650476723,1.24872650476723
16133842.908512,,1600.09936565437,1.24407988808917,2.40119353601307E-7,1.25257340272923,1.25257340272923
16133844.079968,,1595.27286088425,1.24727736915985,2.40019968036229E-7,1.2563953025038,1.2563953025038
16133845.251424,,1590.54966694451,1.25042818172149,2.39922509334147E-7,1.26019236653596,1.26019236653596
16133846.42288,,1586.08002760314,1.25342989733498,2.39824695683619E-7,1.26396475621511,1.26396475621511
16133847.594336,,1581.65392526039,1.25642178660071,2.39728098999194E-7,1.26771263188188,1.26771263188188
16133848.765792,,1577.08933228215,1.25952773422079,2.39634139074658E-7,1.27143615283499,1.27143615283499
16133849.937248,,1572.7902858117,1.26247217000775,2.39540736926253E-7,1.27513547733798,1.27513547733798
16133851.108704,,1568.66031995811,1.26531849854408,2.39448298209346E-7,1.27881076262595,1.27881076262595
16133852.28016,,1564.39992882404,1.26827306648489,2.39357127165463E-7,1.28246216491225,1.28246216491225
16133853.451616,,1560.46342536778,1.27101974452403,2.39268795709154E-7,1.2860898393951,1.2860898393951
16133854.623072,,1556.53328929706,1.27377815748256,2.39181782632789E-7,1.28969394026422,1.28969394026422
16133855.794528,,1552.59800625635,1.27655652962198,2.3909608793637E-7,1.29327462070735,1.29327462070735
16133856.965984,,1548.88282250915,1.27919465595159,2.39015463932046E-7,1.29683203291677,1.29683203291677
16133858.13744,,1545.24630250414,1.28179129888444,2.38936918911482E-7,1.30036632809579,1.30036632809579
16133859.308896,,1541.65273582076,1.28437136279391,2.38856447027921E-7,1.30387765646514,1.30387765646514
16133860.480352,,1538.11199190658,1.2869273195528,2.38777648472752E-7,1.30736616726939,1.30736616726939
16133861.651808,,1534.51051905282,1.28954130557781,2.38695351140037E-7,1.31083200878328,1.31083200878328
16133862.823264,,1530.67947541956,1.29233776325805,2.38610112805906E-7,1.314275328318,1.314275328318
16133863.99472,,1526.66566129053,1.29528531845113,2.38518029037446E-7,1.3176962722275,1.3176962722275
16133865.166176,,1522.24189365581,1.29855509476379,2.38416412367846E-7,1.32109498591465,1.32109498591465
16133866.337632,,1517.60789617519,1.30200431812298,2.38311651869146E-7,1.32447161383749,1.32447161383749
16133867.509088,,1513.159163083,1.30533905705692,2.38204863093608E-7,1.3278262995153,1.3278262995153
16133868.680544,,1508.4233139645,1.30891450339143,2.3809807431807E-7,1.33115918553475,1.33115918553475
16133869.852,,1503.69537101639,1.31251049674176,2.37990322111034E-7,1.33447041355594,1.33447041355594
16133871.023456,,1499.06071026643,1.31606155313749,2.37883330507812E-7,1.33776012431842,1.33776012431842
16133872.194912,,1494.36200423025,1.31968827370597,2.37773550023937E-7,1.34102845764718,1.34102845764718
16133873.366368,,1489.74368643651,1.32327933882534,2.37664428730035E-7,1.34427555245859,1.34427555245859
16133874.537824,,1492.68024505526,1.32099291401474,0,1.34378084096078,1.34378084096078
16133875.70928,,1499.12183716761,1.31601454911404,0,1.3396026152554,1.3396026152554
16133876.880736,,1505.63068478973,1.31103530736888,0,1.33545154079507,1.33545154079507
16133878.052192,,1511.94063120605,1.30625649488068,0,1.33132744114365,1.33132744114365
16133879.223648,,1518.02400482023,1.3016935829835,0,1.32723014101148,1.32723014101148
16133880.395104,,1523.94792848818,1.29729145499186,0,1.32315946624803,1.32315946624803
16133881.56656,,1529.61572407278,1.29311716251735,0,1.31911524383441,1.31911524383441
16133882.738016,,1534.44116761198,1.28959178282173,0,1.31509730187608,1.31509730187608
16133883.909472,,1538.97304814701,1.28630448045848,0,1.3111054695955,1.3111054695955
16133885.080928,,1543.39273004267,1.28312034673589,0,1.3071395773249,1.3071395773249
16133886.252384,,1547.59217999096,1.28011459979267,0,1.30319945649904,1.30319945649904
16133887.42384,,1551.88220599856,1.27706366605018,0,1.29928493964809,1.29928493964809
16133888.595296,,1556.46619297193,1.27382539105213,0,1.29539586039046,1.29539586039046
16133889.766752,,1560.91481994102,1.27070396557865,0,1.29153205342576,1.29153205342576
16133890.938208,,1565.39913079991,1.26757844048627,0,1.28769335452778,1.28769335452778
16133892.109664,,1569.99476478266,1.26439690650084,0,1.28387960053748,1.28387960053748
16133893.28112,,1574.7511752503,1.26112682844167,0,1.28009062935607,1.28009062935607
16133894.452576,,1579.51031838756,1.25787779164713,0,1.27632627993814,1.27632627993814
16133895.624032,,1584.14383831428,1.25473630453933,0,1.27258639228477,1.27258639228477
16133896.795488,,1589.00345348921,1.25146437003397,0,1.26887080743679,1.26887080743679
16133897.966944,,1593.81061732575,1.2482505097081,0,1.26517936746797,1.26517936746797
16133899.1384,,1598.63102001807,1.24505027758076,0,1.26151191547832,1.26151191547832
16133900.309856,,1603.47010037463,1.24186003855456,0,1.25786829558745,1.25786829558745
16133901.481312,,1608.37441990221,1.23864943022939,0,1.2542483529279,1.2542483529279
16133902.652768,,1613.27006386698,1.23546698301053,0,1.2506519336386,1.2506519336386
16133903.824224,,1618.18409365751,1.23229492345815,0,1.24707888485829,1.24707888485829
16133904.99568,,1623.16901367371,1.22909971900448,0,1.24352905471908,1.24352905471908
16133906.167136,,1627.99233475107,1.22602953971593,0,1.24000229233992,1.24000229233992
16133907.338592,,1633.10959026341,1.22279506610251,0,1.23649844782025,1.23649844782025
16133908.510048,,1638.14924326449,1.21963233516179,0,1.23301737223359,1.23301737223359
16133909.681504,,1643.15265522953,1.21651437609283,0,1.22955891762123,1.22955891762123
16133910.85296,,1648.14991205522,1.21342191925339,0,1.22612293698594,1.22612293698594
16133912.024416,,1653.25512259658,1.21028477048607,0,1.22270928428572,1.22270928428572
16133913.195872,,1658.28469390389,1.20721571645298,0,1.21931781442759,1.21931781442759
16133914.367328,,1663.2733547591,1.20419258567453,0,1.2159483832614,1.2159483832614
16133915.538784,,1668.33608953275,1.20114567466661,0,1.21260084757376,1.21260084757376
16133916.71024,,1673.49653714368,1.19806160099895,0,1.20927506508191,1.20927506508191
16133917.881696,,1678.56662094148,1.19505257873712,0,1.20597089442766,1.20597089442766
16133919.053152,,1683.71932156666,1.19201566284415,0,1.20268819517144,1.20268819517144
16133920.224608,,1688.69532724311,1.18910289446346,0,1.19942682778626,1.19942682778626
16133921.396064,,1693.80136023844,1.18613422648217,0,1.19618665365185,1.19618665365185
16133922.56752,,1698.87112566697,1.18320668400152,0,1.19296753504869,1.19296753504869
16133923.738976,,1704.00252208137,1.18026366667375,0,1.18976933515223,1.18976933515223
16133924.910432,,1709.06647727059,1.17737895454955,0,1.18659191802705,1.18659191802705
16133926.081888,,1714.16351633384,1.17449487232226,0,1.18343514862103,1.18343514862103
16133927.253344,,1719.27392690673,1.17162263162696,0,1.18029889275971,1.18029889275971
16133928.4248,,1724.25258566049,1.16884293090623,0,1.17718301714049,1.17718301714049
16133929.596256,,1729.35837987886,1.16601100190424,0,1.17408738932704,1.17408738932704
16133930.767712,,1734.3922491714,1.16323736331249,0,1.17101187774361,1.17101187774361
16133931.939168,,1739.40436323002,1.16049367090804,0,1.16795635166947,1.16795635166947
16133933.110624,,1744.45661834831,1.15774595300252,0,1.16492068123336,1.16492068123336
16133934.28208,,1749.37781144756,1.15508666153289,0,1.16190473740796,1.16190473740796
16133935.453536,,1754.45474018482,1.15236076590491,0,1.15890839200439,1.15890839200439
16133936.624992,,1759.29307767974,1.14977939511944,0,1.15593151766679,1.15593151766679
16133937.796448,,1764.20158906946,1.14717679648434,0,1.15297398786688,1.15297398786688
16133938.967904,,1769.025122393,1.14463500534382,0,1.15003567689861,1.15003567689861
16133940.13936,,1773.83536379922,1.14211561457221,0,1.14711645987278,1.14711645987278
16133941.310816,,1778.57885378037,1.13964609630817,0,1.14421621271178,1.14421621271178
16133942.482272,,1783.21611454609,1.13724605960275,0,1.14133481214427,1.14133481214427
16133943.653728,,1787.85242020397,1.13486039869977,0,1.13847213569998,1.13847213569998
16133944.825184,,1792.47644211392,1.1324947557241,0,1.13562806170446,1.13562806170446
16133945.99664,,1796.88771375452,1.13025058936873,0,1.13280246927396,1.13280246927396
16133947.168096,,1801.03733891096,1.1281506939914,0,1.12999523831024,1.12999523831024
16133948.339552,,1804.77345543812,1.12626923477665,0,1.12720624949551,1.12720624949551
16133949.511008,,1808.25752962099,1.12452248231098,0,1.12443538428734,1.12443538428734
16133950.682464,,1811.64617261308,1.1228307285701,0,1.1216825249136,1.1216825249136
16133951.85392,,1814.97764178918,1.12117434952713,0,1.11894755436749,1.11894755436749
16133953.025376,,1818.35920106485,1.11949994686117,0,1.11623035640257,1.11623035640257
16133954.196832,,1821.59497374244,1.11790417957119,0,1.11353081552776,1.11353081552776
16133955.368288,,1825.0077862688,1.11622789098287,0,1.1108488170025,1.1108488170025
16133956.539744,,1828.33601869058,1.11459981477423,0,1.10818424683185,1.10818424683185
16133957.7112,,1831.74081892348,1.11294105300621,0,1.10553699176162,1.10553699176162
16133958.882656,,1835.14055177872,1.11129154613298,0,1.10290693927359,1.10290693927359
16133960.054112,,1838.66383844421,1.10958920007204,0,1.10029397758071,1.10029397758071
16133961.225568,,1842.38400997675,1.10779952343496,0,1.09769799562234,1.09769799562234
16133962.397024,,1846.22014751844,1.10596238756534,0,1.09511888305958,1.09511888305958
16133963.56848,,1850.02192770898,1.10414998830264,0,1.0925565302705,1.0925565302705
16133964.739936,,1853.95124132574,1.10228539181256,0,1.09001082834555,1.09001082834555
16133965.911392,,1858.10221955161,1.100325032395,0,1.08748166908288,1.08748166908288
16133967.082848,,1862.34541874472,1.09833093946223,0,1.08496894498379,1.08496894498379
16133968.254304,,1866.5070358106,1.09638455605945,0,1.08247254924812,1.08247254924812
16133969.42576,,1870.85513768048,1.09436079315724,0,1.07999237576974,1.07999237576974
16133970.597216,,1875.45862477206,1.0922290462433,0,1.07752831913201,1.07752831913201
16133971.768672,,1879.94182133848,1.09016368271072,0,1.07508027460332,1.07508027460332
16133972.940128,,1884.5278246506,1.08806178210924,0,1.07264813813264,1.07264813813264
16133974.111584,,1889.2027591141,1.08593030792301,0,1.0702318063451,1.0702318063451
16133975.28304,,1894.03876190099,1.08373719226272,0,1.06783117653756,1.06783117653756
16133976.454496,,1898.86643402513,1.08155972841339,0,1.06544614667431,1.06544614667431
16133977.625952,,1903.65603448989,1.07941107093049,0,1.06307661538267,1.06307661538267
16133978.797408,,1908.57972148182,1.07721424864464,0,1.0607224819487,1.0607224819487
16133979.968864,,1913.83719212991,1.07488181245945,0,1.05838364631296,1.05838364631296
16133981.14032,,1918.87257367652,1.07266069136554,0,1.05606000906619,1.05606000906619
16133982.311776,,1923.93960643541,1.07043813714785,0,1.05375147144514,1.05375147144514
16133983.483232,,1929.2684448631,1.06811419676902,0,1.05145793532834,1.05145793532834
16133984.654688,,1934.57571377227,1.06581325640718,0,1.04917930323194,1.04917930323194
16133985.826144,,1939.8755275342,1.06352897403827,0,1.04691547830557,1.04691547830557
16133986.9976,,1945.24827439134,1.06122683853278,0,1.04466636432823,1.04466636432823
16133988.169056,,1950.77503238623,1.05887286128089,0,1.04243186570415,1.04243186570415
16133989.340512,,1956.31508229843,1.05652750265237,0,1.04021188745883,1.04021188745883
16133990.511968,,1961.88527116886,1.05418367624909,0,1.03800633523488,1.03800633523488
16133991.683424,,1967.57272605631,1.05180516591654,0,1.03581511528812,1.03581511528812
16133992.85488,,1973.32791400745,1.04941327669256,0,1.0336381344835,1.0336381344835
16133994.026336,,1979.18227398837,1.04699546236732,0,1.03147530029122,1.03147530029122
16133995.197792,,1984.80762033604,1.0446866315175,0,1.02932652078275,1.02932652078275
16133996.369248,,1990.73265829646,1.04226992619633,0,1.02719170462694,1.02719170462694
16133997.540704,,1996.84250962217,1.03979395019806,0,1.02507076108613,1.02507076108613
16133998.71216,,2002.79004567817,1.0373993220603,0,1.0229636000123,1.0229636000123
16133999.883616,,2008.80674745959,1.03499233491466,0,1.02087013184324,1.02087013184324
16134001.055072,,2014.94485405864,1.03255268788789,0,1.01879026759874,1.01879026759874
16134002.226528,,2021.13758751947,1.0301074626758,0,1.0167239188768,1.0167239188768
16134003.397984,,2027.33947409701,1.02767471532987,0,1.01467099784988,1.01467099784988
16134004.56944,,2033.59487324387,1.02523713975896,0,1.01263141726119,1.01263141726119
16134005.740896,,2039.96607921523,1.02277096785759,0,1.01060509042092,1.01060509042092
16134006.912352,,2046.42815308441,1.02028650388226,0,1.00859193120263,1.00859193120263
16134008.083808,,2052.9341619138,1.01780216006828,0,1.00659185403953,1.00659185403953
16134009.255264,,2059.33380887391,1.01537492652262,0,1.00460477392087,1.00460477392087
16134010.42672,,2065.93824687145,1.01288701096357,0,1.00263060638833,1.00263060638833
16134011.598176,,2072.56101763319,1.01040935411445,0,1.00066926753243,1.00066926753243
16134012.769632,,2079.225521301,1.00793326878123,0,0.998720673988926,0.998720673988926
16134013.941088,,2086.00758282433,1.00543103247673,0,0.99678474293533,0.99678474293533
16134015.112544,,2092.78608922407,1.00294760099402,0,0.994861392087342,0.994861392087342
16134016.284,,2099.53389951935,1.00049261639555,0,0.992950539695371,0.992950539695371
16134017.455456,,2106.52857865818,0.997965753446733,0,0.991052104541055,0.991052104541055
16134018.626912,,2113.50121072457,0.99546484902833,0,0.989166005933814,0.989166005933814
16134019.798368,,2120.52735536027,0.992962742640224,0,0.987292163707415,0.987292163707415
16134020.969824,,2127.5881757164,0.99046630060735,0,0.985430498216567,0.985430498216567
16134022.14128,,2134.69653921788,0.987971106569148,0,0.983580930333537,0.983580930333537
16134023.312736,,2141.92638712932,0.985451666819057,0,0.981743381444784,0.981743381444784
16135715.58,BEGIN:PULSE:PARAMS
16135715.58,ThResSigmaPerCycle=11.7750774531085
16135715.58,TempSigmaPerCycle=0.000476102702685277
16135715.58,NBinsOn=128
16135715.58,NBinsOff=128
16135715.58,Period=300
16135715.58,Iterations=1
16135715.58,HtrOverLoad=0
16135715.58,NCycRec=285
16135715.58,ThFreqHz=244.140625
16135715.58,NSampPerBin=285
16135715.58,PPMSTemp=0.4498
16135715.58,EstTau=300
16135715.58,ThermOverload=0
16135715.58,ThResCorrFact=1
16135715.58,AvgHtrOnResistance=2222.98039306014
16135715.58,IsAddenda=0
16135715.58,AddendafromTbl=4.52695673673783E-8
16135715.58,AddendafromTblMinMidMax=5.07838840418593E-8|4.08391216855345E-8|6.41160283487889E-8
16135715.58,AddendaOffsetMinMidMax=0|0|0
16135715.58,AddendaErrfromTbl=1.52222547822869E-9
16135715.58,CondfromTbl=7.96500047206916E-8
16135715.58,TempMinMidMax=0.519012238918305|1.05798309457468|1.59695395023105
16135715.58,CondfromTblMinMidMax=9.19283582115437E-8|1.92350970622441E-7|3.21632757153234E-7
16135715.58,DisableTau2Fitting=1
16135715.58,HtrCurrOn=1.2020854813887E-5
16135715.58,StableStartTemperature=0.472259794258235
16135715.58,TimeStamp=16135715.58
16135715.58,PPMSStatus=5905
16135715.58,PuckTemp=
16135715.58,SystemTemp=0.4498
16135715.58,Field=-0.062
16135715.58,Pressure=9.41E-5
16135715.58,SampleTemp=1.1223777
16135715.58,TempRise=0.8559376
16135715.58,SampHC=15338.895
16135715.58,SampHCErr=581.2
16135715.58,AddendaHC=0.045269567
16135715.58,AddendaHCErr=0.001522
16135715.58,TotalHC=35.867907
16135715.58,TotalHCErr=1.357
16135715.58,FitDeviation=1319732.7
16135715.58,TimeConsttau1=156.50095
16135715.58,TimeConsttau2=
16135715.58,SampleCoupling=
16135715.58,DebyeTemp=13.557071
16135715.58,DebyeTempErr=0.1704
16135715.58,CalCorrection=1
16135715.58,ThermCondWire=2.2918652E-7
16135715.58,AddendaOffset=0
16135715.58,END:PULSE:PARAMS
16135716.751456,,6206.80619606741,0.519012238918305,3.46045431262002E-7,0.699655377079397,0.699655377079397
16135717.922912,,5355.99746754896,0.558854716780677,3.45227226924818E-7,0.710059599308912,0.710059599308912
16135719.094368,,4778.57440605759,0.593026486280017,3.44411129099551E-7,0.7203862335967,0.7203862335967
16135720.265824,,4356.09382625915,0.623233519907434,3.43602345551775E-7,0.730635858543311,0.730635858543311
16135721.43728,,4031.17657418764,0.650443780751859,3.42796078115456E-7,0.740809048434466,0.740809048434466
16135722.608736,,3772.23925613535,0.675446727049581,3.42000167696063E-7,0.750906373273239,0.750906373273239
16135723.780192,,3560.00881047987,0.698768695951805,3.41221870056866E-7,0.760928398811986,0.760928398811986
16135724.951648,,3382.43669500037,0.720754464499037,3.40456679602933E-7,0.770875686584053,0.770875686584053
16135726.123104,,3231.24987771253,0.741581907263921,3.39711793583313E-7,0.780748793935231,0.780748793935231
16135727.29456,,3100.69221848499,0.761322096367527,3.3898422777279E-7,0.790548274054991,0.790548274054991
16135728.466016,,2986.81052321356,0.780013903847528,3.38278721823178E-7,0.800274676007472,0.800274676007472
16135729.637472,,2886.34564472469,0.797753486886685,3.37591179739082E-7,0.809928544762253,0.809928544762253
16135730.808928,,2797.11135773894,0.814630930087407,3.36926575229196E-7,0.819510421224879,0.819510421224879
16135731.980384,,2717.12085043803,0.830807653977871,3.36282918810043E-7,0.829020842267175,0.829020842267175
16135733.15184,,2645.08812355869,0.846286933422188,3.35659391282543E-7,0.838460340757324,0.838460340757324
16135734.323296,,2579.64827208545,0.8611496129364,3.35054354248539E-7,0.847829445589723,0.847829445589723
16135735.494752,,2520.10032427214,0.875377290533776,3.34467339594271E-7,0.857128681714616,0.857128681714616
16135736.666208,,2465.63139698636,0.889011626535721,3.33903730627972E-7,0.866358570167512,0.866358570167512
16135737.837664,,2415.61881400137,0.902080334699059,3.33354282102895E-7,0.875519628098373,0.875519628098373
16135739.00912,,2369.58640802238,0.914630262397694,3.32821919730035E-7,0.884612368800592,0.884612368800592
16135740.180576,,2326.96806874858,0.926737491021657,3.32310856533228E-7,0.893637301739753,0.893637301739753
16135741.352032,,2287.3784474426,0.938428637206297,3.31815475147359E-7,0.902594932582176,0.902594932582176
16135742.523488,,2250.66602065091,0.94967301738171,3.31334371231152E-7,0.91148576322325,0.91148576322325
16135743.694944,,2216.41506065625,0.960530711607133,3.30875853803835E-7,0.920310291815554,0.920310291815554
16135744.8664,,2184.38863794713,0.971019194835947,3.30425411338868E-7,0.929069012796766,0.929069012796766
16135746.037856,,2154.51564713826,0.981108316688704,3.29994746680234E-7,0.937762416917371,0.937762416917371
16135747.209312,,2126.39811032683,0.990885805713558,3.29576135950905E-7,0.946390991268154,0.946390991268154
16135748.380768,,2099.97582672206,1.00033242945874,3.29168291838041E-7,0.954955219307493,0.954955219307493
16135749.552224,,2075.19522849825,1.0094286059656,3.28776773192536E-7,0.963455580888446,0.963455580888446
16135750.72368,,2051.84679355549,1.01821619463578,3.28397015905236E-7,0.971892552285641,0.971892552285641
16135751.895136,,2029.86355547867,1.02668919775471,3.28035632082991E-7,0.980266606221955,0.980266606221955
16135753.066592,,2009.04278432409,1.03489822377074,3.27684195678133E-7,0.988578211895007,0.988578211895007
16135754.238048,,1989.41995318884,1.0428040209777,3.27342238576903E-7,0.996827835003443,0.996827835003443
16135755.409504,,1970.92400975132,1.05041053300418,3.27017250599451E-7,1.00501593777303,1.00501593777303
16135756.58096,,1953.33142308946,1.05778885405954,3.26702502610485E-7,1.01314297898256,1.01314297898256
16135757.752416,,1936.55201141048,1.06495988599609,3.26395946612308E-7,1.02120941398954,1.02120941398954
16135758.923872,,1920.82899227672,1.07180106283639,3.2610548202461E-7,1.02921569475573,1.02921569475573
16135760.095328,,1905.96093580564,1.07838117601963,3.25826427709797E-7,1.03716226987244,1.03716226987244
16135761.266784,,1891.97227784047,1.08467287588652,3.25556501613292E-7,1.04504958458569,1.04504958458569
16135762.43824,,1878.58103777113,1.09078947263627,3.25294826021796E-7,1.05287808082112,1.05287808082112
16135763.609696,,1865.9738407022,1.09663341498084,3.25044092589426E-7,1.0606481972088,1.0606481972088
16135764.781152,,1854.12927542248,1.10220111441227,3.24804242801962E-7,1.06836036910777,1.06836036910777
16135765.952608,,1843.08862550645,1.10746144909206,3.2457720762866E-7,1.07601502863045,1.07601502863045
16135767.124064,,1832.89288267807,1.11238132905075,3.24365971294738E-7,1.08361260466685,1.08361260466685
16135768.29552,,1823.39537881425,1.1170189997478,3.24173927624951E-7,1.09115352290857,1.09115352290857
16135769.466976,,1815.09130455352,1.12111795628376,3.23996336967484E-7,1.09863820587271,1.09863820587271
16135770.638432,,1807.191204396,1.1250562938301,3.23829395898044E-7,1.1060670729255,1.1060670729255
16135771.809888,,1799.52943993854,1.12891251229236,3.23668247736376E-7,1.1134405403058,1.1134405403058
16135772.981344,,1791.75868259943,1.13286106869654,3.23500077868317E-7,1.12075902114844,1.12075902114844
16135774.1528,,1782.90282524238,1.13740776518009,3.23311310994845E-7,1.12802292550736,1.12802292550736
16135775.324256,,1772.74332493502,1.14268623475977,3.23082169309627E-7,1.13523266037858,1.13523266037858
16135776.495712,,1762.12500916945,1.1482758616053,3.22849692313873E-7,1.142388629723,1.142388629723
16135777.667168,,1751.44553746614,1.1539743205016,3.22614172578682E-7,1.14949123448906,1.14949123448906
16135778.838624,,1740.69466852707,1.15979021991462,3.22373913191678E-7,1.15654087263517,1.15654087263517
16135780.01008,,1730.28590139326,1.16549857479884,3.22131898378077E-7,1.16353793915203,1.16353793915203
16135781.181536,,1719.81053929037,1.17132215447198,3.21889239908056E-7,1.17048282608476,1.17048282608476
16135782.352992,,1709.42718967861,1.17717421088119,3.21648863492612E-7,1.17737592255485,1.17737592255485
16135783.524448,,1699.28103489693,1.18297084737141,3.21407843420749E-7,1.18421761478199,1.18421761478199
16135784.695904,,1689.26480663459,1.18877078646608,3.21167525519525E-7,1.19100828610568,1.19100828610568
16135785.86736,,1679.54162276801,1.19447630140792,3.2092843641692E-7,1.19774831700673,1.19774831700673
16135787.038816,,1669.85457529502,1.2002359135304,3.20689815428074E-7,1.20443808512856,1.20443808512856
16135788.210272,,1660.46680720493,1.20589079987893,3.2044902941309E-7,1.2110779652984,1.2110779652984
16135789.381728,,1651.16884946158,1.21156409945295,3.20219419614112E-7,1.21766832954822,1.21766832954822
16135790.553184,,1642.21721208925,1.21709565600478,3.19989575758255E-7,1.22420954713565,1.22420954713565
16135791.72464,,1633.34092519986,1.22264939626096,3.19762774641833E-7,1.23070198456462,1.23070198456462
16135792.896096,,1624.64776120947,1.22815622360648,3.19542293061163E-7,1.23714600560592,1.23714600560592
16135794.067552,,1616.21654627472,1.23356232580545,3.19318827255277E-7,1.24354197131757,1.24354197131757
16135795.239008,,1608.01647690592,1.23888299170464,3.19099808530105E-7,1.24989024006504,1.24989024006504
16135796.410464,,1599.73437102542,1.24432091050921,3.18882194146211E-7,1.25619116754136,1.25619116754136
16135797.58192,,1592.00802802027,1.24945300575614,3.18675931520983E-7,1.26244510678704,1.26244510678704
16135798.753376,,1584.30179616513,1.25462958657616,3.18471775407671E-7,1.26865240820981,1.26865240820981
16135799.924832,,1577.01463504166,1.25957873531126,3.18278736996145E-7,1.27481341960432,1.27481341960432
16135801.096288,,1569.75846313089,1.26455996779619,3.18082772873623E-7,1.28092848617158,1.28092848617158
16135802.267744,,1562.70247410522,1.26945547888915,3.17886750236881E-7,1.2869979505383,1.2869979505383
16135803.4392,,1555.99774037658,1.27415529857214,3.17693536282695E-7,1.29302215277613,1.29302215277613
16135804.610656,,1549.49512635885,1.27875884505794,3.17515418997249E-7,1.29900143042067,1.29900143042067
16135805.782112,,1543.35077204922,1.28315047470608,3.1733987633748E-7,1.3049361184904,1.3049361184904
16135806.953568,,1537.08577737133,1.28767069332602,3.17167844530906E-7,1.31082654950544,1.31082654950544
16135808.125024,,1530.69576456823,1.29232583826029,3.16983875823468E-7,1.31667305350622,1.31667305350622
16135809.29648,,1523.45076257059,1.29765935628029,3.16773107603306E-7,1.32247595807191,1.32247595807191
16135810.467936,,1515.51577301692,1.30356968649292,3.16541215749751E-7,1.32823558833883,1.32823558833883
16135811.639392,,1507.39699726774,1.30969284058043,3.16300488248987E-7,1.33395226701862,1.33395226701862
16135812.810848,,1499.13017373871,1.31600813899156,3.16052036871194E-7,1.33962631441637,1.33962631441637
16135813.982304,,1490.72973576177,1.32251040457637,3.15802883322762E-7,1.34525804844854,1.34525804844854
16135815.15376,,1482.36034006125,1.32907551265933,3.15546649553719E-7,1.35084778466076,1.35084778466076
16135816.325216,,1474.06592339763,1.33566914555547,3.15296735320428E-7,1.35639583624553,1.35639583624553
16135817.496672,,1465.88877755603,1.34225644405364,3.15043134691281E-7,1.36190251405977,1.36190251405977
16135818.668128,,1457.62906456553,1.3489996727657,3.14787193493338E-7,1.36736812664223,1.36736812664223
16135819.839584,,1449.3032607113,1.35588972456642,3.14528911726598E-7,1.37279298023077,1.37279298023077
16135821.01104,,1441.24330609615,1.36265046823568,3.14275545154331E-7,1.37817737877954,1.37817737877954
16135822.182496,,1433.42288111477,1.36929736224109,3.14021359382985E-7,1.38352162397599,1.38352162397599
16135823.353952,,1425.42957453241,1.37618165464459,3.1376658846944E-7,1.38882601525777,1.38882601525777
16135824.525408,,1417.65088416711,1.38297071724418,3.13508891844899E-7,1.39409084982954,1.39409084982954
16135825.696864,,1409.93366812186,1.38979527793947,3.13258450983629E-7,1.39931642267959,1.39931642267959
16135826.86832,,1402.39869942423,1.39654609675315,3.13012398688852E-7,1.40450302659636,1.40450302659636
16135828.039776,,1394.87330872814,1.40337630023919,3.12765117595458E-7,1.40965095218489,1.40965095218489
16135829.211232,,1387.47115852261,1.41018213809587,3.12516256618125E-7,1.41476048788308,1.41476048788308
16135830.382688,,1380.17452552505,1.41697758353412,3.12268682953631E-7,1.41983191997782,1.41983191997782
16135831.554144,,1373.16881437444,1.42358461178688,3.12020933746476E-7,1.42486553262107,1.42486553262107
16135832.7256,,1366.06891512017,1.43036456135461,3.11775525108119E-7,1.42986160784578,1.42986160784578
16135833.897056,,1359.17325812562,1.43703207313406,3.11537606289912E-7,1.43482042558167,1.43482042558167
16135835.068512,,1352.38375510368,1.44367799576862,3.11296820274929E-7,1.43974226367093,1.43974226367093
16135836.239968,,1345.73916910209,1.4502614047252,3.11064518821834E-7,1.44462739788378,1.44462739788378
16135837.411424,,1339.28983105961,1.45672781575203,3.10833212110479E-7,1.44947610193393,1.44947610193393
16135838.58288,,1332.85086697446,1.46326033548109,3.10604655567459E-7,1.45428864749389,1.45428864749389
16135839.754336,,1326.60500176776,1.46967131556765,3.10377035251959E-7,1.45906530421025,1.45906530421025
16135840.925792,,1320.29609686125,1.47622268918413,3.10152925789654E-7,1.46380633971872,1.46380633971872
[...]
16552901.086976,,869.837231295656,2.28881297179201,4.35201407928539E-7,2.29110389699383,2.29110389699383
16552902.258432,,870.091857686627,2.28802136903818,4.35197123093531E-7,2.29110390112337,2.29110390112337
16552903.429888,,870.071403743364,2.28808493416576,4.35192838258523E-7,2.29110390385949,2.29110390385949
16552904.601344,,870.37452534612,2.2871433410133,4.35184268588508E-7,2.29110390567236,2.29110390567236
16552905.7728,,869.888936529663,2.28865217448681,4.3517641305766E-7,2.29110390687352,2.29110390687352
16552906.944256,,870.09997559407,2.28799614200321,4.35189981701851E-7,2.29110390766937,2.29110390766937
16552908.115712,,870.198504705976,2.28769000704728,4.35172128222652E-7,2.29110390819668,2.29110390819668
16552909.287168,,869.51466385579,2.28981671775492,4.35160701995965E-7,2.29110390854606,2.29110390854606
16552910.458624,,870.097163508486,2.28800488070621,4.35157845439293E-7,2.29110390877755,2.29110390877755
16552911.63008,,870.220470808469,2.28762177034602,4.35158559578461E-7,2.29110390893093,2.29110390893093
16552912.801536,,869.975129605749,2.28838418285624,4.35166415109309E-7,2.29110390903255,2.29110390903255
16552913.972992,,869.671265187933,2.28932928626001,4.35152846465117E-7,2.29110390909988,2.29110390909988
16552915.144448,,869.695141386295,2.28925499146457,4.35164986830973E-7,2.2911039091445,2.2911039091445
16552916.315904,,870.273847376361,2.28745597834942,4.35158559578461E-7,2.29110390917406,2.29110390917406
16552917.48736,,869.591996209373,2.28957598553064,4.35150704047614E-7,2.29110390919364,2.29110390919364
16552918.658816,,869.912043383855,2.28858032340364,4.3514856163011E-7,2.29110390920662,2.29110390920662
16552919.830272,,869.963987379846,2.28841882213868,4.35162130274301E-7,2.29110390921522,2.29110390921522
16552921.001728,,869.754195183576,2.28907125995244,4.35159273717629E-7,2.29110390922091,2.29110390922091
16552922.173184,,869.848744929088,2.28877716342921,4.35146419212606E-7,2.29110390922469,2.29110390922469
16552923.34464,,869.89578103986,2.28863089083616,4.3514499093427E-7,2.29110390922719,2.29110390922719
16552924.516096,,869.923052964211,2.28854609082164,4.35149275769278E-7,2.29110390922885,2.29110390922885
16552925.687552,,869.759686709199,2.28905417616476,4.35149275769278E-7,2.29110390922994,2.29110390922994
16552926.859008,,869.592447204231,2.28957458177751,4.35154988882621E-7,2.29110390923067,2.29110390923067
16552928.030464,,869.723580591455,2.2891665054854,4.35129279872575E-7,2.29110390923115,2.29110390923115
16552929.20192,,869.419875348295,2.29011187118896,4.35132850568415E-7,2.29110390923147,2.29110390923147
16552930.373376,,869.630834825374,2.28945510500722,4.35136421264254E-7,2.29110390923168,2.29110390923168
16552931.544832,,869.693390465082,2.28926043955742,4.35136421264254E-7,2.29110390923182,2.29110390923182
16552932.716288,,869.558702177213,2.28967962111724,4.35132136429247E-7,2.29110390923192,2.29110390923192
16552933.887744,,869.85500579888,2.28875769215191,4.35135707125086E-7,2.29110390923198,2.29110390923198
16552935.0592,,869.525434674163,2.28978318511244,4.35140706099262E-7,2.29110390923202,2.29110390923202
16552936.230656,,869.66765722907,2.28934051352085,4.3514142023843E-7,2.29110390923205,2.29110390923205
16552937.402112,,869.632293926385,2.28945056402234,4.35142848516766E-7,2.29110390923206,2.29110390923206
16552938.573568,,869.504609323369,2.28984802143316,4.3513427884675E-7,2.29110390923208,2.29110390923208
16552939.745024,,869.762525323893,2.28904534553179,4.35129994011743E-7,2.29110390923208,2.29110390923208
16552940.91648,,869.69047226306,2.28926951977984,4.35135707125086E-7,2.29110390923209,2.29110390923209
16552942.087936,,869.295188534629,2.29050025815052,4.3514142023843E-7,2.29110390923209,2.29110390923209
16552943.259392,,869.577113379061,2.28962231051711,4.3513427884675E-7,2.29110390923209,2.29110390923209
16552944.430848,,869.156706584132,2.29093179663308,4.35126423315903E-7,2.2911039092321,2.2911039092321
16552945.602304,,869.337555522166,2.29036827189795,4.35129994011743E-7,2.2911039092321,2.2911039092321
16552946.77376,,869.601732392482,2.2895456814256,4.3513784954259E-7,2.2911039092321,2.2911039092321
16552947.945216,,869.803327093982,2.28891842432503,4.35128565733407E-7,2.2911039092321,2.2911039092321
16552949.116672,,869.427727964645,2.29008741624221,4.35122138480895E-7,2.2911039092321,2.2911039092321
16552950.288128,,869.260674163442,2.29060779425943,4.35132136429247E-7,2.2911039092321,2.2911039092321
16552951.459584,,869.214142105746,2.2907527925017,4.35125709176735E-7,2.2911039092321,2.2911039092321
16552952.63104,,869.719972632591,2.28917773087437,4.35129279872575E-7,2.2911039092321,2.2911039092321
16552953.802496,,869.595312348034,2.28956566386335,4.35136421264254E-7,2.2911039092321,2.2911039092321
16552954.973952,,869.717823774738,2.2891844166453,4.35129279872575E-7,2.2911039092321,2.2911039092321
16552956.145408,,869.42120180376,2.29010774024281,4.35132850568415E-7,2.2911039092321,2.2911039092321
16552957.316864,,869.3505017275,2.2903279440263,4.35122138480895E-7,2.2911039092321,2.2911039092321
16552958.48832,,869.75926224345,2.28905549664009,4.3513784954259E-7,2.2911039092321,2.2911039092321
16552959.659776,,869.504264444949,2.28984909519193,4.35119996063391E-7,2.2911039092321,2.2911039092321
16552960.831232,,869.408653535065,2.29014681969248,4.35123566759231E-7,2.2911039092321,2.2911039092321
16552962.002688,,869.606374986608,2.28953123157038,4.35132136429247E-7,2.2911039092321,2.2911039092321
16552963.174144,,869.452028628755,2.29001174197517,4.35140706099262E-7,2.2911039092321,2.2911039092321
16552964.3456,,869.342596052931,2.29035257027458,4.35132136429247E-7,2.2911039092321,2.2911039092321
16552965.517056,,869.696176021557,2.2892517721512,4.35129994011743E-7,2.2911039092321,2.2911039092321
16552966.688512,,869.727055904772,2.2891556929166,4.35129994011743E-7,2.2911039092321,2.2911039092321
16552967.859968,,869.703949050579,2.28922758636744,4.35122852620063E-7,2.2911039092321,2.2911039092321
16552969.031424,,869.566926201093,2.2896540208658,4.35128565733407E-7,2.2911039092321,2.2911039092321
16552970.20288,,869.25698661725,2.29061928421312,4.35120710202559E-7,2.2911039092321,2.2911039092321
16552971.374336,,869.502646169282,2.28985413361407,4.35124995037567E-7,2.2911039092321,2.2911039092321
16552972.545792,,869.31346709093,2.29044331261464,4.35129994011743E-7,2.2911039092321,2.2911039092321
16552973.717248,,869.478584267155,2.28992905223681,4.35122138480895E-7,2.2911039092321,2.2911039092321
16552974.888704,,869.619082429959,2.28949168134611,4.35119996063391E-7,2.2911039092321,2.2911039092321
16552976.06016,,869.267704377404,2.29058588932654,4.35131422290079E-7,2.2911039092321,2.2911039092321
16552977.231616,,869.405974095027,2.29015516455561,4.35126423315903E-7,2.2911039092321,2.2911039092321
16552978.403072,,869.442584265848,2.29004115180159,4.35119996063391E-7,2.2911039092321,2.2911039092321
16552979.574528,,869.242103786938,2.29066565870863,4.35119996063391E-7,2.2911039092321,2.2911039092321
16552980.745984,,870.009643976936,2.2882768913585,4.35124280898399E-7,2.2911039092321,2.2911039092321
16552981.91744,,869.665694074982,2.28934662252581,4.35114282950048E-7,2.2911039092321,2.2911039092321
16552983.088896,,869.49001831326,2.2898934507193,4.35121424341727E-7,2.2911039092321,2.2911039092321
16552984.260352,,869.377030836791,2.29024531014606,4.35114997089216E-7,2.2911039092321,2.2911039092321
16552985.431808,,869.520049264977,2.28979995128976,4.35115711228383E-7,2.2911039092321,2.2911039092321
16552986.603264,,869.748915890827,2.28908768377903,4.35119281924223E-7,2.2911039092321,2.2911039092321
16552987.77472,,869.688190759661,2.2892766189216,4.3510999811504E-7,2.2911039092321,2.2911039092321
16552988.946176,,869.69681272018,2.28924979104059,4.35129279872575E-7,2.2911039092321,2.2911039092321
16552990.117632,,869.781891573675,2.28898510128896,4.35135707125086E-7,2.2911039092321,2.2911039092321
16552991.289088,,869.431256336181,2.29007642823909,4.35122138480895E-7,2.2911039092321,2.2911039092321
16552992.460544,,869.782342568533,2.28898369838517,4.35102142584192E-7,2.2911039092321,2.2911039092321
16552993.632,,869.715409625793,2.28919192787471,4.35116425367551E-7,2.2911039092321,2.2911039092321
16552994.803456,,869.161694056678,2.2909162513252,4.35117139506719E-7,2.2911039092321,2.2911039092321
16552995.974912,,869.324874607925,2.29040777499281,4.35120710202559E-7,2.2911039092321,2.2911039092321
16552997.146368,,869.38116937784,2.29023241989102,4.35130708150911E-7,2.2911039092321,2.2911039092321
16552998.317824,,899.82517932653,2.199803964057,0,1.99166387660593,1.99166387660593
16552999.48928,,977.187696506087,2.00385725232465,0,1.53412247605946,1.53412247605946
16553000.660736,,1112.3182776849,1.74584413528278,0,1.23096861799492,1.23096861799492
16553001.832192,,1943.0824287111,1.0621532305862,0,1.0301075340588,1.0301075340588
16553003.003648,,4132.87175215947,0.641483322361235,0,0.897022719313009,0.897022719313009
16553004.175104,,4216.22775223908,0.634452901035995,0,0.808844523871451,0.808844523871451
16553005.34656,,4222.71902734587,0.633916620673016,0,0.750420171204456,0.750420171204456
16553006.518016,,4228.20954486288,0.633464247126361,0,0.711709864563859,0.711709864563859
16553007.689472,,4200.67678630953,0.635744107196411,0,0.686061521504756,0.686061521504756
16553008.860928,,4219.28141189309,0.634200424645854,0,0.669067662277933,0.669067662277933
16553010.032384,,4219.76463961882,0.634160503440331,0,0.65780801674233,0.65780801674233
16553011.20384,,4219.46799111873,0.634185009618907,0,0.650347697347232,0.650347697347232
16553012.375296,,4221.5977745417,0.634009140933128,0,0.645404702889645,0.645404702889645
16553013.546752,,4225.61303482017,0.633678038274158,0,0.642129616004788,0.642129616004788
16553014.718208,,4229.43248374296,0.633363639747977,0,0.639959637018284,0.639959637018284
16553015.889664,,4230.33219195545,0.633289659000694,0,0.638521870947516,0.638521870947516
16553017.06112,,4222.43771267095,0.633939828961216,0,0.637569248232223,0.637569248232223
16553018.232576,,4226.29459416695,0.633621895835743,0,0.636938067641623,0.636938067641623
16553019.404032,,4224.40540323615,0.633777557625828,0,0.636519865417851,0.636519865417851
16553020.575488,,4224.65106278818,0.63375730873712,0,0.636242776574228,0.636242776574228
16553021.746944,,4229.41343584249,0.633365206333729,0,0.63605918542407,0.63605918542407
16553022.9184,,4232.18941530956,0.633137039118565,0,0.635937543173969,0.635937543173969
16553024.089856,,4234.36050455569,0.632958788791005,0,0.635856946494897,0.635856946494897
16553025.261312,,4236.83031157243,0.632756224995771,0,0.63580354543834,0.63580354543834
16553026.432768,,4240.90298084341,0.632422691877259,0,0.635768163424165,0.635768163424165
16553027.604224,,4243.75302958361,0.632189648465672,0,0.635744720312589,0.635744720312589
16553028.77568,,4245.70005397267,0.632030614969659,0,0.635729187576731,0.635729187576731
16553029.947136,,4250.18808950781,0.63166455897714,0,0.635718896029788,0.635718896029788
16553031.118592,,4252.94234163437,0.631440278618186,0,0.635712077144858,0.635712077144858
16553032.290048,,4255.59450974838,0.631224571700578,0,0.635707559146548,0.635707559146548
16553033.461504,,4259.17357841189,0.630933882223773,0,0.635704565649967,0.635704565649967
16553034.63296,,4261.41905528047,0.630751742712374,0,0.63570258224467,0.63570258224467
16553035.804416,,4263.30811356573,0.630598654673861,0,0.635701268096994,0.635701268096994
16553036.975872,,4265.09848356443,0.630453682946785,0,0.635700397380295,0.635700397380295
16553038.147328,,4268.53116460288,0.630176050609688,0,0.63569982046829,0.63569982046829
16553039.318784,,4270.25160386948,0.630037062002525,0,0.635699438222881,0.635699438222881
16553040.49024,,4271.33006522037,0.629949990730048,0,0.635699184957995,0.635699184957995
16553041.661696,,4273.76665779228,0.629753421751923,0,0.635699017151918,0.635699017151918
16553042.833152,,4275.68861217306,0.629598520106797,0,0.635698905968407,0.635698905968407
16553044.004608,,4276.77349356839,0.629511141260107,0,0.63569883230139,0.63569883230139
16553045.176064,,4280.04591225762,0.629247826824628,0,0.635698783491729,0.635698783491729
16553046.34752,,4280.3114421125,0.629226477716927,0,0.635698751151842,0.635698751151842
16553047.518976,,4282.34529627627,0.629063034919067,0,0.635698729724357,0.635698729724357
16553048.690432,,4284.86569430443,0.628860696255136,0,0.635698715527118,0.635698715527118
16553049.861888,,4285.62060663841,0.628800135294874,0,0.635698706120433,0.635698706120433
16553051.033344,,4286.60518147151,0.628721180488719,0,0.635698699887832,0.635698699887832
16553052.2048,,4287.02816159004,0.628687271472221,0,0.635698695758289,0.635698695758289
16553053.376256,,4289.02803196481,0.628527033468901,0,0.635698693022172,0.635698693022172
16553054.547712,,4290.16334519691,0.628436130124512,0,0.635698691209299,0.635698691209299
16553055.719168,,4291.37962527055,0.628338794180435,0,0.635698690008141,0.635698690008141
16553056.890624,,4291.95790679487,0.628292533958735,0,0.635698689212288,0.635698689212288
16553058.06208,,4290.35048153384,0.628421150669655,0,0.635698688684979,0.635698688684979
16553059.233536,,4292.54557962388,0.628245534508832,0,0.635698688335599,0.635698688335599
16553060.404992,,4292.40322442343,0.628256918328912,0,0.635698688104109,0.635698688104109
16553061.576448,,4290.67636511237,0.628395068039335,0,0.635698687950731,0.635698687950731
16553062.747904,,4292.03860834534,0.628286079090191,0,0.635698687849107,0.635698687849107
16553063.91936,,4275.59515012103,0.629606049717813,0,0.635698687781774,0.635698687781774
16553065.090816,,4286.35068772609,0.628741585513627,0,0.635698687737161,0.635698687737161
16553066.262272,,4285.02964419985,0.62884754207105,0,0.635698687707602,0.635698687707602
16553067.433728,,4282.63297793742,0.629039928337629,0,0.635698687688016,0.635698687688016
16553068.605184,,4279.21536543305,0.629314620540383,0,0.63569868767504,0.63569868767504
16553069.77664,,4278.65650321674,0.629359578801065,0,0.635698687666442,0.635698687666442
16553070.948096,,4277.20345084267,0.629476523109037,0,0.635698687660745,0.635698687660745
16553072.119552,,4276.84024080737,0.62950576665266,0,0.635698687656971,0.635698687656971
16553073.291008,,4277.45489374052,0.629456281150993,0,0.63569868765447,0.63569868765447
16553074.462464,,4276.98554073895,0.629494067390028,0,0.635698687652813,0.635698687652813
16553075.63392,,4277.81399176388,0.629427376511788,0,0.635698687651715,0.635698687651715
16553076.805376,,4279.5484384002,0.629287831412406,0,0.635698687650988,0.635698687650988
16553077.976832,,4279.88037061564,0.629261137955788,0,0.635698687650505,0.635698687650505
16553079.148288,,4279.03082894883,0.629329464545082,0,0.635698687650186,0.635698687650186
16553080.319744,,4257.23467193027,0.631091301273885,0,0.635698687649975,0.635698687649975
16553081.4912,,4265.06288149976,0.630456564630405,0,0.635698687649834,0.635698687649834
16553082.662656,,4276.00152301714,0.62957331324359,0,0.635698687649742,0.635698687649742
16553083.834112,,4274.29143010316,0.629711114175725,0,0.63569868764968,0.63569868764968
16553085.005568,,4270.13662670982,0.630046347320539,0,0.635698687649639,0.635698687649639
16553086.177024,,4268.19321027962,0.630203365293198,0,0.635698687649612,0.635698687649612
16553087.34848,,4267.44079168192,0.630264193188117,0,0.635698687649594,0.635698687649594
16553088.519936,,4267.83061041384,0.630232676474791,0,0.635698687649582,0.635698687649582
16553089.691392,,4266.94262806766,0.630304477489273,0,0.635698687649575,0.635698687649575
16553090.862848,,4268.68413144705,0.630163688626007,0,0.635698687649569,0.635698687649569
16553092.034304,,4270.68723837315,0.630001885354015,0,0.635698687649566,0.635698687649566
16553093.20576,,4271.91749928739,0.629902580825919,0,0.635698687649564,0.635698687649564
16553094.377216,,4272.18722074155,0.629880816613481,0,0.635698687649562,0.635698687649562
16553095.548672,,4272.95659144009,0.629818749272676,0,0.635698687649561,0.635698687649561
16553096.720128,,4271.68083310341,0.629921679903751,0,0.63569868764956,0.63569868764956
16553097.891584,,4271.9543482202,0.629899607279056,0,0.63569868764956,0.63569868764956
16553099.06304,,4274.07922375794,0.62972822124242,0,0.63569868764956,0.63569868764956
16553100.234496,,4274.52523114334,0.629692268107946,0,0.63569868764956,0.63569868764956
16553101.405952,,4274.18425250162,0.629719754123554,0,0.635698687649559,0.635698687649559
16553102.577408,,4275.02180301104,0.629652247265748,0,0.635698687649559,0.635698687649559
16553103.748864,,4272.69803874094,0.629839605100493,0,0.635698687649559,0.635698687649559
16553104.92032,,4273.05368798009,0.629810917719506,0,0.635698687649559,0.635698687649559
16553106.091776,,4273.95872854354,0.629737935709209,0,0.635698687649559,0.635698687649559
16553107.263232,,4275.06114568012,0.629649076848453,0,0.635698687649559,0.635698687649559
16553108.434688,,4275.37753183752,0.629623582970699,0,0.635698687649559,0.635698687649559
16553109.606144,,4276.59728722448,0.629525330473212,0,0.635698687649559,0.635698687649559
16553110.7776,,4276.37993423207,0.629542834589511,0,0.635698687649559,0.635698687649559
16553111.949056,,4275.7244264706,0.629595634871421,0,0.635698687649559,0.635698687649559
16553113.120512,,3396.46564730146,0.718924223549564,0,0.635698687649559,0.635698687649559
16553114.291968,,4162.88628235785,0.638920514545117,0,0.635698687649559,0.635698687649559
16553115.463424,,4245.25107532704,0.632067275356594,0,0.635698687649559,0.635698687649559
16553116.63488,,4256.05667336133,0.63118700899589,0,0.635698687649559,0.635698687649559
16553117.806336,,4251.94662457536,0.63152132857219,0,0.635698687649559,0.635698687649559
16553118.977792,,4231.87690240211,0.633162711352544,0,0.635698687649559,0.635698687649559
16553120.149248,,4216.12768443884,0.634461180556656,0,0.635698687649559,0.635698687649559
16553121.320704,,4206.79896191876,0.635234687174598,0,0.635698687649559,0.635698687649559
16553122.49216,,4202.50936412111,0.635591470932188,0,0.635698687649559,0.635698687649559
16553123.663616,,4197.58317381693,0.636002065908646,0,0.635698687649559,0.635698687649559
16553124.835072,,4195.33170136965,0.636190033075855,0,0.635698687649559,0.635698687649559
16553126.006528,,4193.34138147423,0.636356359079972,0,0.635698687649559,0.635698687649559
16553127.177984,,4193.39855170475,0.636351579391427,0,0.635698687649559,0.635698687649559
16553128.34944,,4194.57586051685,0.636253178920424,0,0.635698687649559,0.635698687649559
16553129.520896,,4195.68899541358,0.636160190970481,0,0.635698687649559,0.635698687649559
16553130.692352,,4197.29278618663,0.636026298424403,0,0.635698687649559,0.635698687649559
16553131.863808,,4201.59135082322,0.635667916716826,0,0.635698687649559,0.635698687649559
16553133.035264,,4204.34700899257,0.635438540839401,0,0.635698687649559,0.635698687649559
16553134.20672,,4208.57771216759,0.635086945648277,0,0.635698687649559,0.635698687649559
16553135.378176,,4210.69810428586,0.634910983931316,0,0.635698687649559,0.635698687649559
16553136.549632,,4215.35348544241,0.634525249806225,0,0.635698687649559,0.635698687649559
16553137.721088,,4218.74854820388,0.634244456599624,0,0.635698687649559,0.635698687649559
16553138.892544,,4218.23383042542,0.634286999211183,0,0.635698687649559,0.635698687649559
16553140.064,,4221.2856861,0.634034901292951,0,0.635698687649559,0.635698687649559
16553141.235456,,4224.66085202951,0.633756501889571,0,0.635698687649559,0.635698687649559
16553142.406912,,4227.55698183255,0.633517954193926,0,0.635698687649559,0.635698687649559
16553143.578368,,4230.08730174759,0.633309792732643,0,0.635698687649559,0.635698687649559
16553144.749824,,4231.80808589261,0.633168364960323,0,0.635698687649559,0.635698687649559
16553145.92128,,4234.60345813857,0.63293885270988,0,0.635698687649559,0.635698687649559
16553147.092736,,4237.46838970909,0.632703928939239,0,0.635698687649559,0.635698687649559